Workbook

Sheet Sumar_Complet
A1: Echipă | C1: ELO RATINGS | H1: ELO – STATISTICI ALL-TIME | M1: AISCORE – CALIFICARI WCQ 2026 | Y1: FBREF – CALIFICARI (UEFA) | AE1: SOFASCORE – MECIURI ANALIZATE
A2: Echipă | B2: Confederație | C2: Rang Global | D2: Rating Elo | E2: Trend 1 An | F2: Trend 2 Ani | G2: Trend 5 Ani | H2: Meciuri Total | I2: Victorii | J2: Egaluri | K2: Infrangeri | L2: Rata Victorii % | M2: Goluri Marcate | N2: Goluri PK | O2: Pase Decisive | P2: Carti Rosii | Q2: Carti Galbene | R2: Suturi Total | S2: Suturi pe Poarta | T2: Degajari | U2: Pase Cheie | V2: Centrari Total | W2: Centrari Precise | X2: Faulturi Comise | Y2: xG (FBref) | Z2: npxG (FBref) | AA2: Posesie % (FBref) | AB2: Goluri (FBref) | AC2: Goluri Primite | AD2: Salvari % (FBref) | AE2: Meciuri Analizate | AF2: xG Total (Sfa) | AG2: xG/Meci (Sfa) | AH2: Suturi/Meci (Sfa) | AI2: Posesie % (Sfa)
A3: Spain | B3: UEFA | C3: 1 | D3: 2157 | E3: 0 | F3: 136 | G3: 124 | H3: 782 | I3: 462 | J3: 182 | K3: 138 | L3: 59.1 | M3: 21 | N3: 2 | O3: 15 | Q3: 4 | R3: 137 | S3: 58 | T3: 80 | U3: 101 | V3: 124 | W3: 27 | X3: 59 | AA3: 70.5 | AB3: 20 | AE3: 6 | AF3: 19.5 | AG3: 3.25 | AH3: 137 | AI3: 70.5
A4: Argentina | B4: CONMEBOL | C4: 2 | D4: 2115 | E4: -17 | F4: -29 | G4: 131 | H4: 1111 | I4: 612 | J4: 271 | K4: 228 | L4: 55.1 | M4: 31 | O4: 26 | P4: 3 | Q4: 25 | R4: 213 | S4: 81 | T4: 216 | U4: 167 | V4: 197 | W4: 53 | X4: 193 | AE4: 18 | AH4: 213 | AI4: 63.89
A5: France | B5: UEFA | C5: 3 | D5: 2063 | E5: 8 | F5: -13 | G5: -24 | H5: 940 | I5: 475 | J5: 195 | K5: 270 | L5: 50.5 | M5: 16 | N5: 2 | O5: 12 | P5: 1 | Q5: 6 | R5: 131 | S5: 46 | T5: 59 | U5: 102 | V5: 135 | W5: 29 | X5: 61 | AA5: 68.5 | AB5: 15 | AE5: 6 | AF5: 16.5 | AG5: 2.74 | AH5: 131 | AI5: 68.5
A6: England | B6: UEFA | C6: 4 | D6: 2024 | E6: 40 | F6: 44 | G6: 43 | H6: 1162 | I6: 685 | J6: 262 | K6: 215 | L6: 59 | M6: 22 | N6: 2 | O6: 15 | Q6: 6 | R6: 151 | S6: 63 | T6: 65 | U6: 122 | V6: 190 | W6: 48 | X6: 76 | AA6: 74.5 | AB6: 20 | AE6: 8 | AF6: 20.3 | AG6: 2.54 | AH6: 151 | AI6: 74.38
A7: Brazil | B7: CONMEBOL | C7: 5 | D7: 1991 | E7: -10 | F7: -40 | G7: -160 | H7: 1067 | I7: 672 | J7: 223 | K7: 172 | L7: 63 | M7: 24 | N7: 3 | O7: 14 | P7: 1 | Q7: 40 | R7: 215 | S7: 76 | T7: 231 | U7: 160 | V7: 265 | W7: 62 | X7: 229 | AE7: 18 | AH7: 215 | AI7: 62.11
A8: Portugal | B8: UEFA | C8: 6 | D8: 1989 | E8: -41 | F8: -11 | G8: -50 | H8: 696 | I8: 348 | J8: 159 | K8: 189 | L8: 50 | M8: 20 | N8: 3 | O8: 10 | P8: 1 | Q8: 8 | R8: 150 | S8: 50 | T8: 67 | U8: 110 | V8: 165 | W8: 49 | X8: 42 | AA8: 71.3 | AB8: 20 | AE8: 6 | AF8: 20.6 | AG8: 3.43 | AH8: 150 | AI8: 71.33
A9: Colombia | B9: CONMEBOL | C9: 7 | D9: 1982 | E9: 32 | F9: -29 | G9: 54 | H9: 650 | I9: 267 | J9: 178 | K9: 205 | L9: 41.1 | M9: 28 | N9: 2 | O9: 22 | P9: 1 | Q9: 37 | R9: 247 | S9: 96 | T9: 297 | U9: 201 | V9: 301 | W9: 87 | X9: 253 | AE9: 18 | AH9: 247 | AI9: 56.78
A10: Netherlands | B10: UEFA | C10: 8 | D10: 1948 | E10: -27 | F10: -26 | G10: -1 | H10: 903 | I10: 466 | J10: 197 | K10: 240 | L10: 51.6 | M10: 27 | N10: 5 | O10: 18 | Q10: 6 | R10: 139 | S10: 52 | T10: 112 | U10: 113 | V10: 183 | W10: 55 | X10: 80 | AA10: 66.6 | AB10: 27 | AE10: 8 | AF10: 19.7 | AG10: 2.46 | AH10: 139 | AI10: 66.62
A11: Ecuador | B11: CONMEBOL | C11: 9 | D11: 1938 | E11: 33 | F11: 70 | G11: 145 | H11: 600 | I11: 185 | J11: 161 | K11: 254 | L11: 30.8 | M11: 14 | N11: 2 | O11: 10 | P11: 3 | Q11: 23 | R11: 192 | S11: 70 | T11: 347 | U11: 138 | V11: 233 | W11: 46 | X11: 232 | AE11: 18 | AH11: 192 | AI11: 52.39
A12: Germany | B12: UEFA | C12: 10 | D12: 1932 | E12: 19 | F12: 13 | G12: -3 | H12: 1047 | I12: 606 | J12: 217 | K12: 224 | L12: 57.9 | M12: 16 | N12: 1 | O12: 11 | Q12: 8 | R12: 103 | S12: 37 | T12: 105 | U12: 82 | V12: 130 | W12: 30 | X12: 72 | AA12: 73.2 | AB12: 16 | AE12: 6 | AF12: 12.4 | AG12: 2.07 | AH12: 103 | AI12: 73.17
A13: Norway | B13: UEFA | C13: 11 | D13: 1914 | E13: 48 | F13: 180 | G13: 176 | H13: 888 | I13: 335 | J13: 198 | K13: 355 | L13: 37.7 | M13: 37 | N13: 1 | O13: 29 | Q13: 7 | R13: 155 | S13: 61 | T13: 105 | U13: 121 | V13: 149 | W13: 46 | X13: 71 | AA13: 57.6 | AB13: 35 | AE13: 8 | AF13: 25.3 | AG13: 3.16 | AH13: 155 | AI13: 57.5
A14: Croatia | B14: UEFA | C14: 12 | D14: 1912 | E14: -15 | F14: -56 | G14: 87 | H14: 400 | I14: 210 | J14: 106 | K14: 84 | L14: 52.5 | M14: 26 | N14: 3 | O14: 18 | Q14: 6 | R14: 181 | S14: 68 | T14: 156 | U14: 142 | V14: 242 | W14: 61 | X14: 71 | AA14: 70.3 | AB14: 25 | AE14: 8 | AF14: 22.9 | AG14: 2.86 | AH14: 181 | AI14: 70
A15: Turkey | B15: UEFA | C15: 13 | D15: 1911 | E15: 75 | F15: 162 | G15: 111 | H15: 670 | I15: 264 | J15: 156 | K15: 250 | L15: 39.4 | M15: 19 | N15: 1 | O15: 13 | P15: 1 | Q15: 20 | R15: 105 | S15: 37 | T15: 187 | U15: 80 | V15: 112 | W15: 21 | X15: 74 | AA15: 54.8 | AB15: 17 | AE15: 8 | AF15: 10.6 | AG15: 1.32 | AH15: 105 | AI15: 54.75
A16: Japan | B16: AFC | C16: 14 | D16: 1906 | E16: 49 | F16: 53 | G16: 145 | H16: 836 | I16: 409 | J16: 170 | K16: 257 | L16: 48.9 | M16: 54 | N16: 2 | O16: 40 | Q16: 8 | R16: 241 | S16: 103 | T16: 185 | U16: 189 | V16: 341 | W16: 100 | X16: 169 | AE16: 15 | AH16: 241 | AI16: 69.13
A17: Belgium | B17: UEFA | C17: 15 | D17: 1894 | E17: 47 | F17: -94 | G17: -205 | H17: 878 | I17: 392 | J17: 184 | K17: 302 | L17: 44.6 | M17: 29 | N17: 4 | O17: 19 | Q17: 9 | R17: 178 | S17: 64 | T17: 105 | U17: 134 | V17: 205 | W17: 57 | X17: 77 | AA17: 68.1 | AB17: 29 | AE17: 8 | AF17: 24.4 | AG17: 3.04 | AH17: 178 | AI17: 68.12
A18: Uruguay | B18: CONMEBOL | C18: 16 | D18: 1892 | E18: -9 | F18: -99 | G18: -44 | H18: 1019 | I18: 446 | J18: 252 | K18: 321 | L18: 43.8 | M18: 22 | N18: 1 | O18: 17 | Q18: 38 | R18: 188 | S18: 58 | T18: 343 | U18: 146 | V18: 294 | W18: 60 | X18: 237 | AE18: 18 | AH18: 188 | AI18: 52.67
A19: Switzerland | B19: UEFA | C19: 17 | D19: 1891 | E19: 46 | F19: 87 | G19: 2 | H19: 896 | I19: 319 | J19: 204 | K19: 373 | L19: 35.6 | M19: 14 | N19: 2 | O19: 12 | Q19: 4 | R19: 65 | S19: 32 | T19: 88 | U19: 48 | V19: 98 | W19: 23 | X19: 58 | AA19: 60.8 | AB19: 14 | AE19: 6 | AF19: 8.8 | AG19: 1.47 | AH19: 65 | AI19: 60.5
A20: Mexico | B20: CONCACAF | C20: 18 | D20: 1875 | E20: 62 | F20: 84 | G20: -13 | H20: 1029 | I20: 535 | J20: 237 | K20: 257 | L20: 52 | M20: 17 | N20: 4 | O20: 7 | P20: 1 | Q20: 23 | R20: 224 | S20: 64 | T20: 149 | U20: 159 | V20: 336 | W20: 94 | X20: 197
A21: Senegal | B21: CAF | C21: 21 | D21: 1860 | E21: 75 | F21: 93 | G21: 130 | H21: 706 | I21: 319 | J21: 194 | K21: 193 | L21: 45.2 | M21: 22 | N21: 2 | O21: 15 | Q21: 10 | R21: 66 | S21: 33 | T21: 76 | U21: 48 | V21: 66 | W21: 18 | X21: 57 | AE21: 4 | AH21: 59 | AI21: 63.75
A22: Paraguay | B22: CONMEBOL | C22: 22 | D22: 1834 | E22: 9 | F22: 124 | G22: 63 | H22: 789 | I22: 277 | J22: 209 | K22: 303 | L22: 35.1 | M22: 14 | N22: 1 | O22: 10 | P22: 1 | Q22: 36 | R22: 198 | S22: 67 | T22: 407 | U22: 132 | V22: 277 | W22: 68 | X22: 247 | AE22: 18 | AH22: 198 | AI22: 37.94
A23: Austria | B23: UEFA | C23: 23 | D23: 1830 | E23: -15 | F23: -33 | G23: 84 | H23: 866 | I23: 371 | J23: 185 | K23: 310 | L23: 42.8 | M23: 22 | N23: 2 | O23: 16 | P23: 1 | Q23: 11 | R23: 107 | S23: 54 | T23: 178 | U23: 78 | V23: 159 | W23: 37 | X23: 115 | AA23: 64.3 | AB23: 22 | AE23: 8 | AF23: 20.2 | AG23: 2.53 | AH23: 107 | AI23: 64.25
A24: Morocco | B24: CAF | C24: 24 | D24: 1827 | E24: 15 | F24: 57 | G24: 150 | H24: 730 | I24: 365 | J24: 200 | K24: 165 | L24: 50 | M24: 22 | N24: 2 | O24: 14 | Q24: 11 | R24: 125 | S24: 47 | T24: 108 | U24: 89 | V24: 169 | W24: 52 | X24: 108 | AE24: 8 | AH24: 125 | AI24: 63.5
A25: Canada | B25: CONCACAF | C25: 25 | D25: 1788 | E25: 3 | F25: 68 | G25: 161 | H25: 490 | I25: 190 | J25: 115 | K25: 185 | L25: 38.8 | M25: 54 | N25: 3 | O25: 29 | P25: 1 | Q25: 31 | R25: 248 | S25: 106 | T25: 251 | U25: 189 | V25: 324 | W25: 79 | X25: 277
A26: Scotland | B26: UEFA | C26: 26 | D26: 1782 | E26: 65 | F26: 13 | G26: 104 | H26: 869 | I26: 413 | J26: 188 | K26: 268 | L26: 47.5 | M26: 13 | O26: 7 | Q26: 12 | R26: 67 | S26: 29 | T26: 176 | U26: 54 | V26: 125 | W26: 39 | X26: 76 | AA26: 44.8 | AB26: 12 | AE26: 6 | AF26: 8.6 | AG26: 1.44 | AH26: 67 | AI26: 44.67
A27: Australia | B27: AFC | C27: 28 | D27: 1777 | E27: 2 | F27: 7 | G27: 46 | H27: 637 | I27: 326 | J27: 131 | K27: 180 | L27: 51.2 | M27: 38 | N27: 3 | O27: 22 | P27: 1 | Q27: 23 | R27: 183 | S27: 76 | T27: 264 | U27: 132 | V27: 284 | W27: 87 | X27: 162 | AE27: 16 | AH27: 183 | AI27: 54.5
A28: Algeria | B28: CAF | C28: 29 | D28: 1772 | E28: 68 | F28: 131 | G28: 27 | H28: 690 | I28: 311 | J28: 183 | K28: 196 | L28: 45.1 | M28: 24 | N28: 2 | O28: 14 | Q28: 16 | R28: 78 | S28: 34 | T28: 58 | U28: 59 | V28: 96 | W28: 25 | X28: 48 | AE28: 4 | AH28: 57 | AI28: 69
A29: Iran | B29: AFC | C29: 29 | D29: 1772 | E29: -29 | F29: -48 | G29: -21 | H29: 670 | I29: 384 | J29: 154 | K29: 132 | L29: 57.3 | M29: 35 | N29: 2 | O29: 22 | P29: 3 | Q29: 23 | R29: 172 | S29: 78 | T29: 188 | U29: 132 | V29: 150 | W29: 41 | X29: 101 | AE29: 10 | AH29: 156 | AI29: 55.2
A30: South Korea | B30: AFC | C30: 33 | D30: 1758 | E30: -12 | F30: 21 | G30: -4 | H30: 1052 | I30: 573 | J30: 258 | K30: 221 | L30: 54.5 | M30: 40 | N30: 3 | O30: 32 | Q30: 16 | R30: 219 | S30: 90 | T30: 157 | U30: 167 | V30: 291 | W30: 78 | X30: 147 | AE30: 14 | AH30: 206 | AI30: 72.43
A31: Czechia | B31: UEFA | C31: 35 | D31: 1740 | E31: -9 | F31: -37 | G31: -27 | H31: 884 | I31: 426 | J31: 197 | K31: 261 | L31: 48.2 | M31: 22 | N31: 1 | O31: 17 | Q31: 9 | R31: 163 | S31: 61 | T31: 273 | U31: 124 | V31: 284 | W31: 81 | X31: 156 | AA31: 55.2 | AB31: 22 | AE31: 10 | AF31: 19.7 | AG31: 1.97 | AH31: 163 | AI31: 55.3
A32: Panama | B32: CONCACAF | C32: 38 | D32: 1730 | E32: 1 | F32: 20 | G32: 184 | H32: 594 | I32: 197 | J32: 145 | K32: 252 | L32: 33.2 | M32: 38 | O32: 14 | Q32: 22 | R32: 175 | S32: 53 | T32: 225 | U32: 113 | V32: 310 | W32: 66 | X32: 238 | AE32: 10 | AH32: 166 | AI32: 61.8
A33: United States | B33: CONCACAF | C33: 39 | D33: 1726 | E33: 32 | F33: -59 | G33: -71 | H33: 827 | I33: 367 | J33: 173 | K33: 287 | L33: 44.4 | M33: 21 | N33: 2 | O33: 15 | P33: 1 | Q33: 15 | R33: 182 | S33: 62 | T33: 170 | U33: 138 | V33: 316 | W33: 85 | X33: 189
A34: Uzbekistan | B34: AFC | C34: 42 | D34: 1714 | E34: 7 | F34: 45 | G34: 144 | H34: 367 | I34: 180 | J34: 75 | K34: 112 | L34: 49 | M34: 27 | N34: 1 | O34: 22 | P34: 1 | Q34: 23 | R34: 173 | S34: 62 | T34: 174 | U34: 139 | V34: 221 | W34: 62 | X34: 112 | AE34: 11 | AH34: 181 | AI34: 52.2
A35: Sweden | B35: UEFA | C35: 43 | D35: 1712 | E35: -48 | F35: 38 | G35: -136 | H35: 1120 | I35: 549 | J35: 235 | K35: 336 | L35: 49 | M35: 10 | N35: 1 | O35: 7 | Q35: 15 | R35: 76 | S35: 25 | T35: 196 | U35: 59 | V35: 129 | W35: 37 | X35: 111 | AA35: 50.5 | AB35: 10 | AE35: 8 | AF35: 9.7 | AG35: 1.21 | AH35: 76 | AI35: 50.38
A36: Egypt | B36: CAF | C36: 48 | D36: 1696 | E36: 30 | F36: 63 | G36: 98 | H36: 885 | I36: 447 | J36: 221 | K36: 217 | L36: 50.5 | M36: 20 | N36: 3 | O36: 14 | Q36: 14 | R36: 14 | S36: 14 | U36: 10
A37: Ivory Coast | B37: CAF | C37: 49 | D37: 1695 | E37: 108 | F37: 60 | G37: 54 | H37: 693 | I37: 349 | J37: 178 | K37: 166 | L37: 50.4 | M37: 25 | N37: 4 | O37: 18 | Q37: 11 | R37: 15 | S37: 15 | U37: 10
A38: Jordan | B38: AFC | C38: 52 | D38: 1680 | E38: 56 | F38: 71 | G38: 204 | H38: 585 | I38: 207 | J38: 158 | K38: 220 | L38: 35.4 | M38: 32 | N38: 4 | O38: 21 | Q38: 22 | R38: 162 | S38: 60 | T38: 254 | U38: 115 | V38: 184 | W38: 48 | X38: 152 | AE38: 12 | AH38: 148 | AI38: 40.92
A39: DR Congo | B39: CAF | C39: 55 | D39: 1652 | E39: 69 | F39: 99 | G39: 178 | H39: 549 | I39: 226 | J39: 151 | K39: 172 | L39: 41.2 | M39: 17 | O39: 15 | Q39: 12 | R39: 20 | S39: 13 | T39: 22 | U39: 18 | V39: 16 | W39: 6 | X39: 12 | AE39: 2 | AH39: 28 | AI39: 39
A40: Tunisia | B40: CAF | C40: 58 | D40: 1628 | E40: 15 | F40: -43 | G40: -19 | H40: 777 | I40: 330 | J40: 216 | K40: 231 | L40: 42.5 | M40: 22 | N40: 5 | O40: 10 | Q40: 19 | R40: 97 | S40: 40 | T40: 109 | U40: 70 | V40: 91 | W40: 28 | X40: 115 | AE40: 6 | AH40: 47 | AI40: 60.67
...

Sheet Meciuri
A1: Echipă | B1: Adversar | C1: Dată | D1: Competiție | E1: Teren | F1: xG | G1: Șuturi total | H1: Șuturi pe poartă | I1: Șuturi pe lângă | J1: Șuturi blocate | K1: Șuturi în careu | L1: Șuturi afara careului | M1: Șanse mari | N1: Șanse mari ratate | O1: Bara | P1: Posesie (%) | Q1: Pase total | R1: Pase precise | S1: Centrări | T1: Mingi lungi | U1: Dribling | V1: Intrări treime finală | W1: Mingi prin apărare | X1: Cornere | Y1: Aruncări margine | Z1: Lovituri libere | AA1: Lovituri de poartă | AB1: Fault comise | AC1: Fault suferite (treime fin.) | AD1: Ofsaid | AE1: Galbene | AF1: Roșii | AG1: Recuperări | AH1: Interceptări | AI1: Degajări | AJ1: Dueluri aeriene | AK1: Dueluri sol | AL1: Tackle reușit | AM1: Tackle total | AN1: Save-uri
A2: England | B2: Albania | C2: 2025-03-21 | D2: World Cup Qual. UEFA K | E2: Acasă | F2: 1.81 | G2: 12 | H2: 6 | I2: 2 | J2: 4 | K2: 11 | L2: 1 | M2: 4 | N2: 3 | O2: 2 | P2: 74 | Q2: 863 | R2: 811 | S2: 6 | T2: 17 | U2: 9 | V2: 101 | W2: 3 | X2: 4 | Y2: 16 | Z2: 7 | AA2: 1 | AB2: 9 | AC2: 1 | AD2: 2 | AE2: 0 | AG2: 31 | AH2: 4 | AI2: 9 | AJ2: 16 | AK2: 31 | AL2: 10 | AM2: 15 | AN2: 0
A3: England | B3: Latvia | C3: 2025-03-24 | D3: World Cup Qual. UEFA K | E3: Acasă | F3: 5.22 | G3: 27 | H3: 8 | I3: 9 | J3: 10 | K3: 21 | L3: 6 | M3: 5 | N3: 4 | O3: 0 | P3: 73 | Q3: 696 | R3: 660 | S3: 11 | T3: 11 | U3: 12 | V3: 93 | X3: 10 | Y3: 16 | Z3: 13 | AA3: 1 | AB3: 11 | AC3: 3 | AD3: 0 | AE3: 1 | AG3: 43 | AH3: 11 | AI3: 5 | AJ3: 6 | AK3: 32 | AL3: 6 | AM3: 7 | AN3: 1
A4: England | B4: Andorra | C4: 2025-06-07 | D4: World Cup Qual. UEFA K | E4: Deplasare | F4: 2.28 | G4: 20 | H4: 10 | I4: 7 | J4: 3 | K4: 12 | L4: 8 | M4: 6 | N4: 5 | O4: 0 | P4: 83 | Q4: 751 | R4: 683 | S4: 5 | T4: 25 | U4: 13 | V4: 113 | W4: 2 | X4: 12 | Y4: 17 | Z4: 13 | AA4: 4 | AB4: 8 | AC4: 3 | AD4: 2 | AG4: 46 | AH4: 5 | AI4: 5 | AJ4: 16 | AK4: 39 | AL4: 6 | AM4: 14 | AN4: 0
A5: England | B5: Andorra | C5: 2025-09-06 | D5: World Cup Qual. UEFA K | E5: Acasă | F5: 1.97 | G5: 11 | H5: 7 | I5: 3 | J5: 1 | K5: 9 | L5: 2 | M5: 3 | N5: 2 | O5: 0 | P5: 83 | Q5: 787 | R5: 710 | S5: 6 | T5: 22 | U5: 5 | V5: 124 | W5: 1 | X5: 8 | Y5: 21 | Z5: 8 | AA5: 1 | AB5: 10 | AD5: 5 | AE5: 1 | AG5: 53 | AH5: 2 | AI5: 4 | AJ5: 14 | AK5: 23 | AL5: 9 | AM5: 11 | AN5: 0
A6: England | B6: Serbia | C6: 2025-09-09 | D6: World Cup Qual. UEFA K | E6: Deplasare | F6: 3.56 | G6: 24 | H6: 12 | I6: 4 | J6: 8 | K6: 16 | L6: 8 | M6: 7 | N6: 3 | O6: 0 | P6: 70 | Q6: 588 | R6: 536 | S6: 5 | T6: 21 | U6: 10 | V6: 75 | W6: 1 | X6: 6 | Y6: 10 | Z6: 10 | AA6: 3 | AB6: 10 | AC6: 6 | AD6: 2 | AE6: 1 | AF6: 0 | AG6: 44 | AH6: 3 | AI6: 10 | AJ6: 12 | AK6: 32 | AL6: 5 | AM6: 11 | AN6: 0
A7: England | B7: Latvia | C7: 2025-10-14 | D7: World Cup Qual. UEFA K | E7: Deplasare | F7: 2.9 | G7: 24 | H7: 7 | I7: 10 | J7: 7 | K7: 13 | L7: 11 | M7: 3 | N7: 1 | O7: 0 | P7: 72 | Q7: 719 | R7: 661 | S7: 5 | T7: 17 | U7: 12 | V7: 100 | W7: 1 | X7: 9 | Y7: 17 | Z7: 10 | AA7: 3 | AB7: 5 | AC7: 8 | AD7: 1 | AE7: 1 | AG7: 48 | AH7: 12 | AI7: 9 | AJ7: 2 | AK7: 37 | AL7: 6 | AM7: 14 | AN7: 1
A8: England | B8: Serbia | C8: 2025-11-13 | D8: World Cup Qual. UEFA K | E8: Acasă | F8: 0.93 | G8: 19 | H8: 6 | I8: 7 | J8: 6 | K8: 10 | L8: 9 | M8: 2 | N8: 2 | O8: 2 | P8: 70 | Q8: 647 | R8: 588 | S8: 5 | T8: 23 | U8: 5 | V8: 88 | W8: 3 | X8: 6 | Y8: 18 | Z8: 10 | AA8: 4 | AB8: 13 | AC8: 2 | AD8: 2 | AE8: 0 | AG8: 42 | AH8: 3 | AI8: 9 | AJ8: 7 | AK8: 24 | AL8: 9 | AM8: 11 | AN8: 1
A9: England | B9: Albania | C9: 2025-11-16 | D9: World Cup Qual. UEFA K | E9: Deplasare | F9: 1.66 | G9: 14 | H9: 7 | I9: 4 | J9: 3 | K9: 10 | L9: 4 | M9: 3 | N9: 1 | O9: 0 | P9: 70 | Q9: 686 | R9: 633 | S9: 5 | T9: 12 | U9: 8 | V9: 68 | W9: 3 | X9: 5 | Y9: 16 | Z9: 9 | AA9: 3 | AB9: 10 | AC9: 1 | AD9: 2 | AE9: 2 | AG9: 40 | AH9: 14 | AI9: 14 | AJ9: 14 | AK9: 30 | AL9: 8 | AM9: 13 | AN9: 3
A10: France | B10: Ukraine | C10: 2025-09-05 | D10: World Cup Qual. UEFA D | E10: Deplasare | F10: 2.21 | G10: 16 | H10: 6 | I10: 6 | J10: 4 | K10: 9 | L10: 7 | M10: 5 | N10: 3 | O10: 0 | P10: 56 | Q10: 538 | R10: 477 | S10: 1 | T10: 26 | U10: 9 | V10: 84 | W10: 4 | X10: 4 | Y10: 21 | Z10: 10 | AA10: 2 | AB10: 8 | AC10: 0 | AD10: 0 | AG10: 45 | AH10: 7 | AI10: 15 | AJ10: 7 | AK10: 38 | AL10: 14 | AM10: 19 | AN10: 2
A11: France | B11: Iceland | C11: 2025-09-09 | D11: World Cup Qual. UEFA D | E11: Acasă | F11: 3.77 | G11: 20 | H11: 8 | I11: 8 | J11: 4 | K11: 13 | L11: 7 | M11: 7 | N11: 5 | O11: 1 | P11: 63 | Q11: 623 | R11: 560 | S11: 4 | T11: 24 | U11: 10 | V11: 82 | W11: 3 | X11: 3 | Y11: 19 | Z11: 12 | AA11: 5 | AB11: 12 | AC11: 3 | AD11: 3 | AE11: 3 | AF11: 1 | AG11: 45 | AH11: 3 | AI11: 7 | AJ11: 7 | AK11: 37 | AL11: 9 | AM11: 14 | AN11: 1
A12: France | B12: Azerbaijan | C12: 2025-10-10 | D12: World Cup Qual. UEFA D | E12: Acasă | F12: 3.23 | G12: 33 | H12: 9 | I12: 13 | J12: 11 | K12: 23 | L12: 10 | M12: 2 | N12: 1 | O12: 1 | P12: 77 | Q12: 717 | R12: 649 | S12: 8 | T12: 28 | U12: 16 | V12: 104 | W12: 1 | X12: 10 | Y12: 21 | Z12: 14 | AA12: 2 | AB12: 8 | AC12: 7 | AD12: 0 | AE12: 1 | AG12: 54 | AH12: 4 | AI12: 7 | AJ12: 20 | AK12: 39 | AL12: 6 | AM12: 9 | AN12: 0
A13: France | B13: Iceland | C13: 2025-10-13 | D13: World Cup Qual. UEFA D | E13: Deplasare | F13: 2.5 | G13: 20 | H13: 9 | I13: 8 | J13: 3 | K13: 13 | L13: 7 | M13: 5 | N13: 4 | O13: 0 | P13: 70 | Q13: 717 | R13: 654 | S13: 7 | T13: 27 | U13: 6 | V13: 93 | X13: 9 | Y13: 23 | Z13: 16 | AA13: 4 | AB13: 12 | AC13: 4 | AD13: 1 | AE13: 1 | AG13: 38 | AH13: 9 | AI13: 13 | AJ13: 14 | AK13: 28 | AL13: 6 | AM13: 6 | AN13: 0
A14: France | B14: Ukraine | C14: 2025-11-13 | D14: World Cup Qual. UEFA D | E14: Acasă | F14: 2.7 | G14: 25 | H14: 10 | I14: 8 | J14: 7 | K14: 11 | L14: 14 | M14: 8 | N14: 5 | O14: 2 | P14: 71 | Q14: 718 | R14: 663 | S14: 1 | T14: 16 | U14: 11 | V14: 66 | W14: 5 | X14: 7 | Y14: 19 | Z14: 9 | AA14: 3 | AB14: 9 | AC14: 5 | AD14: 0 | AE14: 1 | AG14: 46 | AH14: 8 | AI14: 8 | AJ14: 9 | AK14: 31 | AL14: 7 | AM14: 10 | AN14: 0
A15: France | B15: Azerbaijan | C15: 2025-11-16 | D15: World Cup Qual. UEFA D | E15: Deplasare | F15: 2.05 | G15: 17 | H15: 4 | I15: 5 | J15: 8 | K15: 12 | L15: 5 | M15: 6 | N15: 4 | O15: 0 | P15: 74 | Q15: 610 | R15: 549 | S15: 8 | T15: 20 | U15: 13 | V15: 60 | W15: 0 | X15: 8 | Y15: 21 | Z15: 10 | AA15: 4 | AB15: 12 | AC15: 5 | AD15: 0 | AE15: 0 | AG15: 52 | AH15: 7 | AI15: 9 | AJ15: 16 | AK15: 41 | AL15: 9 | AM15: 18 | AN15: 0
A16: Croatia | B16: Gibraltar | C16: 2025-06-06 | D16: World Cup Qual. UEFA L | E16: Deplasare | F16: 4.08 | G16: 30 | H16: 13 | I16: 10 | J16: 7 | K16: 24 | L16: 6 | M16: 13 | N16: 7 | O16: 0 | P16: 68 | Q16: 485 | R16: 432 | S16: 10 | T16: 31 | U16: 3 | V16: 65 | W16: 4 | X16: 12 | Y16: 19 | Z16: 9 | AA16: 5 | AB16: 10 | AC16: 2 | AD16: 6 | AE16: 1 | AG16: 52 | AH16: 8 | AI16: 16 | AJ16: 16 | AK16: 36 | AL16: 13 | AM16: 24 | AN16: 0
A17: Croatia | B17: Czechia | C17: 2025-06-09 | D17: World Cup Qual. UEFA L | E17: Acasă | F17: 3.62 | G17: 18 | H17: 11 | I17: 2 | J17: 5 | K17: 11 | L17: 6 | M17: 6 | N17: 2 | O17: 0 | P17: 61 | Q17: 533 | R17: 465 | S17: 2 | T17: 30 | U17: 9 | V17: 59 | W17: 2 | X17: 0 | Y17: 14 | Z17: 9 | AA17: 4 | AB17: 3 | AC17: 5 | AD17: 3 | AE17: 0 | AG17: 55 | AH17: 13 | AI17: 23 | AJ17: 16 | AK17: 26 | AL17: 2 | AM17: 8 | AN17: 3
A18: Croatia | B18: Faroe Islands | C18: 2025-09-05 | D18: World Cup Qual. UEFA L | E18: Deplasare | F18: 2.03 | G18: 26 | H18: 8 | I18: 9 | J18: 9 | K18: 22 | L18: 4 | M18: 3 | N18: 2 | O18: 1 | P18: 74 | Q18: 610 | R18: 549 | S18: 12 | T18: 22 | U18: 9 | V18: 73 | W18: 1 | X18: 17 | Y18: 21 | Z18: 12 | AA18: 7 | AB18: 8 | AC18: 2 | AD18: 2 | AE18: 1 | AG18: 49 | AH18: 4 | AI18: 32 | AJ18: 28 | AK18: 25 | AL18: 4 | AM18: 5 | AN18: 3
A19: Croatia | B19: Montenegro | C19: 2025-09-08 | D19: World Cup Qual. UEFA L | E19: Acasă | F19: 3.3 | G19: 32 | H19: 13 | I19: 13 | J19: 6 | K19: 22 | L19: 10 | M19: 6 | N19: 4 | O19: 0 | P19: 75 | Q19: 704 | R19: 628 | S19: 7 | T19: 28 | U19: 10 | V19: 78 | W19: 4 | X19: 7 | Y19: 21 | Z19: 6 | AA19: 0 | AB19: 10 | AC19: 1 | AD19: 2 | AE19: 1 | AF19: 0 | AG19: 60 | AH19: 8 | AI19: 14 | AJ19: 13 | AK19: 28 | AL19: 8 | AM19: 13 | AN19: 1
A20: Croatia | B20: Czechia | C20: 2025-10-09 | D20: World Cup Qual. UEFA L | E20: Deplasare | F20: 0.69 | G20: 10 | H20: 2 | I20: 4 | J20: 4 | K20: 5 | L20: 5 | M20: 3 | N20: 3 | O20: 0 | P20: 58 | Q20: 418 | R20: 342 | S20: 2 | T20: 24 | U20: 10 | V20: 48 | W20: 1 | X20: 6 | Y20: 28 | Z20: 17 | AA20: 8 | AB20: 8 | AC20: 1 | AD20: 0 | AE20: 2 | AG20: 38 | AH20: 11 | AI20: 30 | AJ20: 21 | AK20: 38 | AL20: 7 | AM20: 14 | AN20: 2
A21: Croatia | B21: Gibraltar | C21: 2025-10-12 | D21: World Cup Qual. UEFA L | E21: Acasă | F21: 3.98 | G21: 28 | H21: 10 | I21: 14 | J21: 4 | K21: 22 | L21: 6 | M21: 5 | N21: 3 | O21: 1 | P21: 80 | Q21: 613 | R21: 545 | S21: 13 | T21: 36 | U21: 11 | V21: 92 | W21: 1 | X21: 18 | Y21: 16 | Z21: 6 | AA21: 2 | AB21: 7 | AC21: 3 | AD21: 6 | AG21: 45 | AH21: 1 | AI21: 5 | AJ21: 16 | AK21: 30 | AL21: 7 | AM21: 12 | AN21: 0
A22: Croatia | B22: Faroe Islands | C22: 2025-11-14 | D22: World Cup Qual. UEFA L | E22: Acasă | F22: 2.04 | G22: 20 | H22: 4 | I22: 12 | J22: 4 | K22: 14 | L22: 6 | M22: 5 | N22: 3 | O22: 2 | P22: 81 | Q22: 644 | R22: 565 | S22: 8 | T22: 36 | U22: 8 | V22: 89 | W22: 2 | X22: 11 | Y22: 19 | Z22: 11 | AA22: 2 | AB22: 9 | AC22: 3 | AD22: 1 | AE22: 0 | AG22: 42 | AH22: 4 | AI22: 14 | AJ22: 20 | AK22: 26 | AL22: 4 | AM22: 8 | AN22: 3
A23: Croatia | B23: Montenegro | C23: 2025-11-17 | D23: World Cup Qual. UEFA L | E23: Deplasare | F23: 3.14 | G23: 17 | H23: 7 | I23: 5 | J23: 5 | K23: 14 | L23: 3 | M23: 5 | N23: 3 | O23: 1 | P23: 63 | Q23: 491 | R23: 438 | S23: 7 | T23: 27 | U23: 11 | V23: 55 | X23: 3 | Y23: 15 | Z23: 16 | AA23: 9 | AB23: 16 | AC23: 5 | AD23: 0 | AE23: 1 | AG23: 38 | AH23: 4 | AI23: 22 | AJ23: 13 | AK23: 38 | AL23: 8 | AM23: 13 | AN23: 3
A24: Norway | B24: Moldova | C24: 2025-03-22 | D24: World Cup Qual. UEFA I | E24: Deplasare | F24: 3.12 | G24: 24 | H24: 8 | I24: 6 | J24: 10 | K24: 17 | L24: 7 | M24: 6 | N24: 3 | O24: 0 | P24: 69 | Q24: 622 | R24: 565 | S24: 5 | T24: 22 | U24: 10 | V24: 60 | W24: 1 | X24: 6 | Y24: 15 | Z24: 10 | AA24: 5 | AB24: 9 | AC24: 1 | AD24: 0 | AE24: 1 | AG24: 46 | AH24: 2 | AI24: 17 | AJ24: 12 | AK24: 25 | AL24: 4 | AM24: 5 | AN24: 4
A25: Norway | B25: Israel | C25: 2025-03-25 | D25: World Cup Qual. UEFA I | E25: Deplasare | F25: 3.76 | G25: 23 | H25: 12 | I25: 5 | J25: 6 | K25: 20 | L25: 3 | M25: 7 | N25: 3 | O25: 3 | P25: 56 | Q25: 568 | R25: 526 | S25: 9 | T25: 16 | U25: 5 | V25: 70 | W25: 2 | X25: 7 | Y25: 12 | Z25: 7 | AA25: 6 | AB25: 9 | AC25: 1 | AD25: 1 | AE25: 2 | AG25: 42 | AH25: 6 | AI25: 8 | AJ25: 11 | AK25: 22 | AL25: 7 | AM25: 11 | AN25: 4
A26: Norway | B26: Italy | C26: 2025-06-06 | D26: World Cup Qual. UEFA I | E26: Acasă | F26: 1.51 | G26: 8 | H26: 4 | I26: 1 | J26: 3 | K26: 5 | L26: 3 | M26: 2 | O26: 1 | P26: 38 | Q26: 355 | R26: 305 | S26: 0 | T26: 32 | U26: 7 | V26: 58 | W26: 3 | X26: 6 | Y26: 17 | Z26: 10 | AA26: 5 | AB26: 11 | AC26: 2 | AD26: 0 | AE26: 2 | AG26: 37 | AH26: 5 | AI26: 22 | AJ26: 7 | AK26: 27 | AL26: 7 | AM26: 10 | AN26: 1
A27: Norway | B27: Estonia | C27: 2025-06-09 | D27: World Cup Qual. UEFA I | E27: Deplasare | F27: 2.39 | G27: 19 | H27: 3 | I27: 10 | J27: 6 | K27: 15 | L27: 4 | M27: 2 | N27: 1 | O27: 2 | P27: 62 | Q27: 587 | R27: 512 | S27: 7 | T27: 21 | U27: 14 | V27: 56 | W27: 3 | X27: 2 | Y27: 24 | Z27: 7 | AA27: 5 | AB27: 9 | AE27: 1 | AG27: 44 | AH27: 10 | AI27: 10 | AJ27: 16 | AK27: 35 | AL27: 8 | AM27: 15 | AN27: 2
A28: Norway | B28: Moldova | C28: 2025-09-09 | D28: World Cup Qual. UEFA I | E28: Acasă | F28: 8.1 | G28: 34 | H28: 17 | I28: 8 | J28: 9 | K28: 29 | L28: 5 | M28: 17 | N28: 8 | O28: 1 | P28: 71 | Q28: 654 | R28: 594 | S28: 7 | T28: 16 | U28: 16 | V28: 79 | W28: 3 | X28: 4 | Y28: 16 | Z28: 9 | AA28: 2 | AB28: 6 | AC28: 4 | AE28: 0 | AG28: 55 | AH28: 8 | AI28: 12 | AJ28: 10 | AK28: 42 | AL28: 16 | AM28: 17 | AN28: 0
A29: Norway | B29: Israel | C29: 2025-10-11 | D29: World Cup Qual. UEFA I | E29: Acasă | F29: 2.51 | G29: 16 | H29: 5 | I29: 6 | J29: 5 | K29: 12 | L29: 4 | M29: 5 | N29: 2 | O29: 0 | P29: 54 | Q29: 475 | R29: 427 | S29: 6 | T29: 18 | U29: 11 | V29: 46 | W29: 2 | X29: 5 | Y29: 16 | Z29: 10 | AA29: 2 | AB29: 10 | AC29: 4 | AD29: 1 | AE29: 0 | AG29: 36 | AH29: 7 | AI29: 3 | AJ29: 9 | AK29: 29 | AL29: 5 | AM29: 8 | AN29: 1
A30: Norway | B30: Estonia | C30: 2025-11-13 | D30: World Cup Qual. UEFA I | E30: Acasă | F30: 2.48 | G30: 18 | H30: 7 | I30: 5 | J30: 6 | K30: 15 | L30: 3 | M30: 6 | N30: 2 | O30: 0 | P30: 68 | Q30: 661 | R30: 601 | S30: 10 | T30: 13 | U30: 10 | V30: 72 | X30: 8 | Y30: 19 | Z30: 17 | AA30: 2 | AB30: 9 | AC30: 4 | AD30: 2 | AG30: 41 | AH30: 3 | AI30: 14 | AJ30: 19 | AK30: 37 | AL30: 4 | AM30: 10 | AN30: 2
A31: Norway | B31: Italy | C31: 2025-11-16 | D31: World Cup Qual. UEFA I | E31: Deplasare | F31: 1.42 | G31: 13 | H31: 5 | I31: 8 | J31: 0 | K31: 8 | L31: 5 | M31: 3 | N31: 1 | O31: 0 | P31: 42 | Q31: 394 | R31: 333 | S31: 2 | T31: 27 | U31: 8 | V31: 47 | X31: 2 | Y31: 13 | Z31: 15 | AA31: 8 | AB31: 8 | AC31: 2 | AE31: 2 | AG31: 41 | AH31: 6 | AI31: 19 | AJ31: 17 | AK31: 32 | AL31: 4 | AM31: 9 | AN31: 3
A32: Portugal | B32: Armenia | C32: 2025-09-06 | D32: World Cup Qual. UEFA F | E32: Deplasare | F32: 3.67 | G32: 24 | H32: 9 | I32: 11 | J32: 4 | K32: 20 | L32: 4 | M32: 9 | N32: 6 | O32: 1 | P32: 71 | Q32: 634 | R32: 590 | S32: 11 | T32: 29 | U32: 15 | V32: 56 | X32: 4 | Y32: 16 | Z32: 10 | AA32: 5 | AB32: 7 | AC32: 3 | AD32: 1 | AE32: 0 | AG32: 35 | AH32: 4 | AI32: 10 | AJ32: 8 | AK32: 36 | AL32: 6 | AM32: 11 | AN32: 3
A33: Portugal | B33: Hungary | C33: 2025-09-09 | D33: World Cup Qual. UEFA F | E33: Deplasare | F33: 2.35 | G33: 15 | H33: 7 | I33: 5 | J33: 3 | K33: 10 | L33: 5 | M33: 4 | N33: 2 | O33: 0 | P33: 69 | Q33: 697 | R33: 644 | S33: 4 | T33: 32 | U33: 6 | V33: 91 | W33: 1 | X33: 6 | Y33: 19 | Z33: 5 | AA33: 5 | AB33: 9 | AC33: 2 | AD33: 4 | AE33: 2 | AG33: 44 | AH33: 8 | AI33: 11 | AJ33: 14 | AK33: 15 | AL33: 1 | AM33: 4 | AN33: 0
A34: Portugal | B34: Ireland | C34: 2025-10-11 | D34: World Cup Qual. UEFA F | E34: Acasă | F34: 3.74 | G34: 30 | H34: 6 | I34: 16 | J34: 8 | K34: 17 | L34: 13 | M34: 3 | N34: 2 | O34: 1 | P34: 70 | Q34: 674 | R34: 618 | S34: 11 | T34: 14 | U34: 3 | V34: 70 | X34: 9 | Y34: 16 | Z34: 8 | AA34: 1 | AC34: 1 | AD34: 4 | AE34: 2 | AG34: 52 | AH34: 6 | AI34: 10 | AJ34: 21 | AK34: 26 | AL34: 8 | AM34: 16 | AN34: 0
A35: Portugal | B35: Hungary | C35: 2025-10-14 | D35: World Cup Qual. UEFA F | E35: Acasă | F35: 2.33 | G35: 20 | H35: 8 | I35: 8 | J35: 4 | K35: 11 | L35: 9 | M35: 4 | N35: 2 | O35: 2 | P35: 65 | Q35: 602 | R35: 545 | S35: 7 | T35: 27 | U35: 4 | V35: 62 | X35: 5 | Y35: 14 | Z35: 12 | AA35: 9 | AC35: 3 | AD35: 1 | AE35: 2 | AG35: 41 | AH35: 4 | AI35: 19 | AJ35: 15 | AK35: 21 | AL35: 6 | AM35: 7 | AN35: 4
A36: Portugal | B36: Ireland | C36: 2025-11-13 | D36: World Cup Qual. UEFA F | E36: Deplasare | F36: 2.66 | G36: 27 | H36: 5 | I36: 10 | J36: 12 | K36: 14 | L36: 13 | M36: 1 | N36: 1 | O36: 0 | P36: 77 | Q36: 798 | R36: 732 | S36: 4 | T36: 11 | U36: 5 | V36: 71 | X36: 9 | Y36: 13 | Z36: 5 | AA36: 3 | AB36: 6 | AC36: 1 | AD36: 2 | AE36: 2 | AF36: 1 | AG36: 41 | AH36: 7 | AI36: 10 | AJ36: 12 | AK36: 24 | AL36: 10 | AM36: 15 | AN36: 1
A37: Portugal | B37: Armenia | C37: 2025-11-16 | D37: World Cup Qual. UEFA F | E37: Acasă | F37: 5.8 | G37: 34 | H37: 15 | I37: 11 | J37: 8 | K37: 24 | L37: 10 | M37: 8 | N37: 3 | O37: 3 | P37: 76 | Q37: 659 | R37: 598 | S37: 12 | T37: 21 | U37: 9 | V37: 62 | X37: 7 | Y37: 20 | Z37: 8 | AA37: 0 | AB37: 7 | AC37: 8 | AD37: 3 | AE37: 0 | AG37: 40 | AH37: 5 | AI37: 7 | AJ37: 12 | AK37: 32 | AL37: 9 | AM37: 14 | AN37: 1
A38: Germany | B38: Slovakia | C38: 2025-09-04 | D38: World Cup Qual. UEFA A | E38: Deplasare | F38: 1.69 | G38: 14 | H38: 4 | I38: 6 | J38: 4 | K38: 9 | L38: 5 | M38: 2 | N38: 2 | O38: 0 | P38: 70 | Q38: 616 | R38: 547 | S38: 4 | T38: 24 | U38: 6 | V38: 59 | W38: 0 | X38: 8 | Y38: 22 | Z38: 12 | AA38: 5 | AB38: 18 | AC38: 3 | AD38: 0 | AE38: 2 | AG38: 34 | AH38: 4 | AI38: 13 | AJ38: 15 | AK38: 27 | AL38: 7 | AM38: 11 | AN38: 3
A39: Germany | B39: Northern Ireland | C39: 2025-09-07 | D39: World Cup Qual. UEFA A | E39: Acasă | F39: 1.64 | G39: 11 | H39: 6 | I39: 3 | J39: 2 | K39: 7 | L39: 4 | M39: 4 | N39: 2 | O39: 1 | P39: 80 | Q39: 751 | R39: 679 | S39: 2 | T39: 20 | U39: 10 | V39: 56 | W39: 2 | X39: 3 | Y39: 24 | Z39: 13 | AA39: 6 | AB39: 9 | AC39: 3 | AD39: 2 | AE39: 1 | AG39: 36 | AH39: 6 | AI39: 22 | AJ39: 17 | AK39: 31 | AL39: 7 | AM39: 9 | AN39: 0
A40: Germany | B40: Luxembourg | C40: 2025-10-10 | D40: World Cup Qual. UEFA A | E40: Acasă | F40: 3.35 | G40: 31 | H40: 8 | I40: 17 | J40: 6 | K40: 21 | L40: 10 | M40: 7 | N40: 4 | O40: 1 | P40: 85 | Q40: 810 | R40: 735 | S40: 10 | T40: 16 | U40: 3 | V40: 89 | W40: 4 | X40: 7 | Y40: 24 | Z40: 4 | AA40: 1 | AB40: 10 | AC40: 3 | AD40: 2 | AE40: 0 | AF40: 0 | AG40: 57 | AH40: 6 | AI40: 4 | AJ40: 15 | AK40: 18 | AL40: 4 | AM40: 11 | AN40: 1
...

Sheet Sumar_Echipe
A1: Echipă | B1: Meciuri | C1: xG (tot.) | D1: xG mediu/meci | E1: Șuturi total | F1: Șuturi/meci | G1: Șuturi pe poartă | H1: Șuturi/poartă per meci | I1: Șuturi în careu | J1: Șanse mari | K1: Cornere (tot.) | L1: Cornere/meci | M1: Posesie medie (%) | N1: Pase precise (tot.) | O1: Centrări (tot.) | P1: Fault comise (tot.) | Q1: Galbene (tot.) | R1: Roșii (tot.) | S1: Ofsaid (tot.) | T1: Recuperări (tot.) | U1: Interceptări (tot.) | V1: Degajări (tot.) | W1: Save-uri (tot.) | X1: Cel mai bun jucător | Y1: Rating mediu
A2: England | B2: =COUNTIF(Meciuri!$A:$A,$A2) | C2: =SUMIF(Meciuri!$A:$A,$A2,Meciuri!$F:$F) | D2: =IFERROR(ROUND(AVERAGEIF(Meciuri!$A:$A,$A2,Meciuri!$F:$F),2),"") | E2: =SUMIF(Meciuri!$A:$A,$A2,Meciuri!$G:$G) | F2: =IFERROR(ROUND(AVERAGEIF(Meciuri!$A:$A,$A2,Meciuri!$G:$G),2),"") | G2: =SUMIF(Meciuri!$A:$A,$A2,Meciuri!$H:$H) | H2: =IFERROR(ROUND(AVERAGEIF(Meciuri!$A:$A,$A2,Meciuri!$H:$H),2),"") | I2: =SUMIF(Meciuri!$A:$A,$A2,Meciuri!$K:$K) | J2: =SUMIF(Meciuri!$A:$A,$A2,Meciuri!$M:$M) | K2: =SUMIF(Meciuri!$A:$A,$A2,Meciuri!$X:$X) | L2: =IFERROR(ROUND(AVERAGEIF(Meciuri!$A:$A,$A2,Meciuri!$X:$X),2),"") | M2: =IFERROR(ROUND(AVERAGEIF(Meciuri!$A:$A,$A2,Meciuri!$P:$P),2),"") | N2: =SUMIF(Meciuri!$A:$A,$A2,Meciuri!$R:$R) | O2: =SUMIF(Meciuri!$A:$A,$A2,Meciuri!$S:$S) | P2: =SUMIF(Meciuri!$A:$A,$A2,Meciuri!$AB:$AB) | Q2: =SUMIF(Meciuri!$A:$A,$A2,Meciuri!$AE:$AE) | R2: =SUMIF(Meciuri!$A:$A,$A2,Meciuri!$AF:$AF) | S2: =SUMIF(Meciuri!$A:$A,$A2,Meciuri!$AD:$AD) | T2: =SUMIF(Meciuri!$A:$A,$A2,Meciuri!$AG:$AG) | U2: =SUMIF(Meciuri!$A:$A,$A2,Meciuri!$AH:$AH) | V2: =SUMIF(Meciuri!$A:$A,$A2,Meciuri!$AI:$AI) | W2: =SUMIF(Meciuri!$A:$A,$A2,Meciuri!$AN:$AN) | X2: Harry Kane | Y2: 7.88
A3: France | B3: =COUNTIF(Meciuri!$A:$A,$A3) | C3: =SUMIF(Meciuri!$A:$A,$A3,Meciuri!$F:$F) | D3: =IFERROR(ROUND(AVERAGEIF(Meciuri!$A:$A,$A3,Meciuri!$F:$F),2),"") | E3: =SUMIF(Meciuri!$A:$A,$A3,Meciuri!$G:$G) | F3: =IFERROR(ROUND(AVERAGEIF(Meciuri!$A:$A,$A3,Meciuri!$G:$G),2),"") | G3: =SUMIF(Meciuri!$A:$A,$A3,Meciuri!$H:$H) | H3: =IFERROR(ROUND(AVERAGEIF(Meciuri!$A:$A,$A3,Meciuri!$H:$H),2),"") | I3: =SUMIF(Meciuri!$A:$A,$A3,Meciuri!$K:$K) | J3: =SUMIF(Meciuri!$A:$A,$A3,Meciuri!$M:$M) | K3: =SUMIF(Meciuri!$A:$A,$A3,Meciuri!$X:$X) | L3: =IFERROR(ROUND(AVERAGEIF(Meciuri!$A:$A,$A3,Meciuri!$X:$X),2),"") | M3: =IFERROR(ROUND(AVERAGEIF(Meciuri!$A:$A,$A3,Meciuri!$P:$P),2),"") | N3: =SUMIF(Meciuri!$A:$A,$A3,Meciuri!$R:$R) | O3: =SUMIF(Meciuri!$A:$A,$A3,Meciuri!$S:$S) | P3: =SUMIF(Meciuri!$A:$A,$A3,Meciuri!$AB:$AB) | Q3: =SUMIF(Meciuri!$A:$A,$A3,Meciuri!$AE:$AE) | R3: =SUMIF(Meciuri!$A:$A,$A3,Meciuri!$AF:$AF) | S3: =SUMIF(Meciuri!$A:$A,$A3,Meciuri!$AD:$AD) | T3: =SUMIF(Meciuri!$A:$A,$A3,Meciuri!$AG:$AG) | U3: =SUMIF(Meciuri!$A:$A,$A3,Meciuri!$AH:$AH) | V3: =SUMIF(Meciuri!$A:$A,$A3,Meciuri!$AI:$AI) | W3: =SUMIF(Meciuri!$A:$A,$A3,Meciuri!$AN:$AN) | X3: Kylian Mbappé | Y3: 8.43
A4: Croatia | B4: =COUNTIF(Meciuri!$A:$A,$A4) | C4: =SUMIF(Meciuri!$A:$A,$A4,Meciuri!$F:$F) | D4: =IFERROR(ROUND(AVERAGEIF(Meciuri!$A:$A,$A4,Meciuri!$F:$F),2),"") | E4: =SUMIF(Meciuri!$A:$A,$A4,Meciuri!$G:$G) | F4: =IFERROR(ROUND(AVERAGEIF(Meciuri!$A:$A,$A4,Meciuri!$G:$G),2),"") | G4: =SUMIF(Meciuri!$A:$A,$A4,Meciuri!$H:$H) | H4: =IFERROR(ROUND(AVERAGEIF(Meciuri!$A:$A,$A4,Meciuri!$H:$H),2),"") | I4: =SUMIF(Meciuri!$A:$A,$A4,Meciuri!$K:$K) | J4: =SUMIF(Meciuri!$A:$A,$A4,Meciuri!$M:$M) | K4: =SUMIF(Meciuri!$A:$A,$A4,Meciuri!$X:$X) | L4: =IFERROR(ROUND(AVERAGEIF(Meciuri!$A:$A,$A4,Meciuri!$X:$X),2),"") | M4: =IFERROR(ROUND(AVERAGEIF(Meciuri!$A:$A,$A4,Meciuri!$P:$P),2),"") | N4: =SUMIF(Meciuri!$A:$A,$A4,Meciuri!$R:$R) | O4: =SUMIF(Meciuri!$A:$A,$A4,Meciuri!$S:$S) | P4: =SUMIF(Meciuri!$A:$A,$A4,Meciuri!$AB:$AB) | Q4: =SUMIF(Meciuri!$A:$A,$A4,Meciuri!$AE:$AE) | R4: =SUMIF(Meciuri!$A:$A,$A4,Meciuri!$AF:$AF) | S4: =SUMIF(Meciuri!$A:$A,$A4,Meciuri!$AD:$AD) | T4: =SUMIF(Meciuri!$A:$A,$A4,Meciuri!$AG:$AG) | U4: =SUMIF(Meciuri!$A:$A,$A4,Meciuri!$AH:$AH) | V4: =SUMIF(Meciuri!$A:$A,$A4,Meciuri!$AI:$AI) | W4: =SUMIF(Meciuri!$A:$A,$A4,Meciuri!$AN:$AN) | X4: Lovro Majer | Y4: 8.2
A5: Norway | B5: =COUNTIF(Meciuri!$A:$A,$A5) | C5: =SUMIF(Meciuri!$A:$A,$A5,Meciuri!$F:$F) | D5: =IFERROR(ROUND(AVERAGEIF(Meciuri!$A:$A,$A5,Meciuri!$F:$F),2),"") | E5: =SUMIF(Meciuri!$A:$A,$A5,Meciuri!$G:$G) | F5: =IFERROR(ROUND(AVERAGEIF(Meciuri!$A:$A,$A5,Meciuri!$G:$G),2),"") | G5: =SUMIF(Meciuri!$A:$A,$A5,Meciuri!$H:$H) | H5: =IFERROR(ROUND(AVERAGEIF(Meciuri!$A:$A,$A5,Meciuri!$H:$H),2),"") | I5: =SUMIF(Meciuri!$A:$A,$A5,Meciuri!$K:$K) | J5: =SUMIF(Meciuri!$A:$A,$A5,Meciuri!$M:$M) | K5: =SUMIF(Meciuri!$A:$A,$A5,Meciuri!$X:$X) | L5: =IFERROR(ROUND(AVERAGEIF(Meciuri!$A:$A,$A5,Meciuri!$X:$X),2),"") | M5: =IFERROR(ROUND(AVERAGEIF(Meciuri!$A:$A,$A5,Meciuri!$P:$P),2),"") | N5: =SUMIF(Meciuri!$A:$A,$A5,Meciuri!$R:$R) | O5: =SUMIF(Meciuri!$A:$A,$A5,Meciuri!$S:$S) | P5: =SUMIF(Meciuri!$A:$A,$A5,Meciuri!$AB:$AB) | Q5: =SUMIF(Meciuri!$A:$A,$A5,Meciuri!$AE:$AE) | R5: =SUMIF(Meciuri!$A:$A,$A5,Meciuri!$AF:$AF) | S5: =SUMIF(Meciuri!$A:$A,$A5,Meciuri!$AD:$AD) | T5: =SUMIF(Meciuri!$A:$A,$A5,Meciuri!$AG:$AG) | U5: =SUMIF(Meciuri!$A:$A,$A5,Meciuri!$AH:$AH) | V5: =SUMIF(Meciuri!$A:$A,$A5,Meciuri!$AI:$AI) | W5: =SUMIF(Meciuri!$A:$A,$A5,Meciuri!$AN:$AN) | X5: Martin Ødegaard | Y5: 8.76
A6: Portugal | B6: =COUNTIF(Meciuri!$A:$A,$A6) | C6: =SUMIF(Meciuri!$A:$A,$A6,Meciuri!$F:$F) | D6: =IFERROR(ROUND(AVERAGEIF(Meciuri!$A:$A,$A6,Meciuri!$F:$F),2),"") | E6: =SUMIF(Meciuri!$A:$A,$A6,Meciuri!$G:$G) | F6: =IFERROR(ROUND(AVERAGEIF(Meciuri!$A:$A,$A6,Meciuri!$G:$G),2),"") | G6: =SUMIF(Meciuri!$A:$A,$A6,Meciuri!$H:$H) | H6: =IFERROR(ROUND(AVERAGEIF(Meciuri!$A:$A,$A6,Meciuri!$H:$H),2),"") | I6: =SUMIF(Meciuri!$A:$A,$A6,Meciuri!$K:$K) | J6: =SUMIF(Meciuri!$A:$A,$A6,Meciuri!$M:$M) | K6: =SUMIF(Meciuri!$A:$A,$A6,Meciuri!$X:$X) | L6: =IFERROR(ROUND(AVERAGEIF(Meciuri!$A:$A,$A6,Meciuri!$X:$X),2),"") | M6: =IFERROR(ROUND(AVERAGEIF(Meciuri!$A:$A,$A6,Meciuri!$P:$P),2),"") | N6: =SUMIF(Meciuri!$A:$A,$A6,Meciuri!$R:$R) | O6: =SUMIF(Meciuri!$A:$A,$A6,Meciuri!$S:$S) | P6: =SUMIF(Meciuri!$A:$A,$A6,Meciuri!$AB:$AB) | Q6: =SUMIF(Meciuri!$A:$A,$A6,Meciuri!$AE:$AE) | R6: =SUMIF(Meciuri!$A:$A,$A6,Meciuri!$AF:$AF) | S6: =SUMIF(Meciuri!$A:$A,$A6,Meciuri!$AD:$AD) | T6: =SUMIF(Meciuri!$A:$A,$A6,Meciuri!$AG:$AG) | U6: =SUMIF(Meciuri!$A:$A,$A6,Meciuri!$AH:$AH) | V6: =SUMIF(Meciuri!$A:$A,$A6,Meciuri!$AI:$AI) | W6: =SUMIF(Meciuri!$A:$A,$A6,Meciuri!$AN:$AN) | X6: João Cancelo | Y6: 8.25
A7: Germany | B7: =COUNTIF(Meciuri!$A:$A,$A7) | C7: =SUMIF(Meciuri!$A:$A,$A7,Meciuri!$F:$F) | D7: =IFERROR(ROUND(AVERAGEIF(Meciuri!$A:$A,$A7,Meciuri!$F:$F),2),"") | E7: =SUMIF(Meciuri!$A:$A,$A7,Meciuri!$G:$G) | F7: =IFERROR(ROUND(AVERAGEIF(Meciuri!$A:$A,$A7,Meciuri!$G:$G),2),"") | G7: =SUMIF(Meciuri!$A:$A,$A7,Meciuri!$H:$H) | H7: =IFERROR(ROUND(AVERAGEIF(Meciuri!$A:$A,$A7,Meciuri!$H:$H),2),"") | I7: =SUMIF(Meciuri!$A:$A,$A7,Meciuri!$K:$K) | J7: =SUMIF(Meciuri!$A:$A,$A7,Meciuri!$M:$M) | K7: =SUMIF(Meciuri!$A:$A,$A7,Meciuri!$X:$X) | L7: =IFERROR(ROUND(AVERAGEIF(Meciuri!$A:$A,$A7,Meciuri!$X:$X),2),"") | M7: =IFERROR(ROUND(AVERAGEIF(Meciuri!$A:$A,$A7,Meciuri!$P:$P),2),"") | N7: =SUMIF(Meciuri!$A:$A,$A7,Meciuri!$R:$R) | O7: =SUMIF(Meciuri!$A:$A,$A7,Meciuri!$S:$S) | P7: =SUMIF(Meciuri!$A:$A,$A7,Meciuri!$AB:$AB) | Q7: =SUMIF(Meciuri!$A:$A,$A7,Meciuri!$AE:$AE) | R7: =SUMIF(Meciuri!$A:$A,$A7,Meciuri!$AF:$AF) | S7: =SUMIF(Meciuri!$A:$A,$A7,Meciuri!$AD:$AD) | T7: =SUMIF(Meciuri!$A:$A,$A7,Meciuri!$AG:$AG) | U7: =SUMIF(Meciuri!$A:$A,$A7,Meciuri!$AH:$AH) | V7: =SUMIF(Meciuri!$A:$A,$A7,Meciuri!$AI:$AI) | W7: =SUMIF(Meciuri!$A:$A,$A7,Meciuri!$AN:$AN) | X7: Florian Wirtz | Y7: 7.98
A8: Netherlands | B8: =COUNTIF(Meciuri!$A:$A,$A8) | C8: =SUMIF(Meciuri!$A:$A,$A8,Meciuri!$F:$F) | D8: =IFERROR(ROUND(AVERAGEIF(Meciuri!$A:$A,$A8,Meciuri!$F:$F),2),"") | E8: =SUMIF(Meciuri!$A:$A,$A8,Meciuri!$G:$G) | F8: =IFERROR(ROUND(AVERAGEIF(Meciuri!$A:$A,$A8,Meciuri!$G:$G),2),"") | G8: =SUMIF(Meciuri!$A:$A,$A8,Meciuri!$H:$H) | H8: =IFERROR(ROUND(AVERAGEIF(Meciuri!$A:$A,$A8,Meciuri!$H:$H),2),"") | I8: =SUMIF(Meciuri!$A:$A,$A8,Meciuri!$K:$K) | J8: =SUMIF(Meciuri!$A:$A,$A8,Meciuri!$M:$M) | K8: =SUMIF(Meciuri!$A:$A,$A8,Meciuri!$X:$X) | L8: =IFERROR(ROUND(AVERAGEIF(Meciuri!$A:$A,$A8,Meciuri!$X:$X),2),"") | M8: =IFERROR(ROUND(AVERAGEIF(Meciuri!$A:$A,$A8,Meciuri!$P:$P),2),"") | N8: =SUMIF(Meciuri!$A:$A,$A8,Meciuri!$R:$R) | O8: =SUMIF(Meciuri!$A:$A,$A8,Meciuri!$S:$S) | P8: =SUMIF(Meciuri!$A:$A,$A8,Meciuri!$AB:$AB) | Q8: =SUMIF(Meciuri!$A:$A,$A8,Meciuri!$AE:$AE) | R8: =SUMIF(Meciuri!$A:$A,$A8,Meciuri!$AF:$AF) | S8: =SUMIF(Meciuri!$A:$A,$A8,Meciuri!$AD:$AD) | T8: =SUMIF(Meciuri!$A:$A,$A8,Meciuri!$AG:$AG) | U8: =SUMIF(Meciuri!$A:$A,$A8,Meciuri!$AH:$AH) | V8: =SUMIF(Meciuri!$A:$A,$A8,Meciuri!$AI:$AI) | W8: =SUMIF(Meciuri!$A:$A,$A8,Meciuri!$AN:$AN) | X8: Cody Gakpo | Y8: 8.04
A9: Switzerland | B9: =COUNTIF(Meciuri!$A:$A,$A9) | C9: =SUMIF(Meciuri!$A:$A,$A9,Meciuri!$F:$F) | D9: =IFERROR(ROUND(AVERAGEIF(Meciuri!$A:$A,$A9,Meciuri!$F:$F),2),"") | E9: =SUMIF(Meciuri!$A:$A,$A9,Meciuri!$G:$G) | F9: =IFERROR(ROUND(AVERAGEIF(Meciuri!$A:$A,$A9,Meciuri!$G:$G),2),"") | G9: =SUMIF(Meciuri!$A:$A,$A9,Meciuri!$H:$H) | H9: =IFERROR(ROUND(AVERAGEIF(Meciuri!$A:$A,$A9,Meciuri!$H:$H),2),"") | I9: =SUMIF(Meciuri!$A:$A,$A9,Meciuri!$K:$K) | J9: =SUMIF(Meciuri!$A:$A,$A9,Meciuri!$M:$M) | K9: =SUMIF(Meciuri!$A:$A,$A9,Meciuri!$X:$X) | L9: =IFERROR(ROUND(AVERAGEIF(Meciuri!$A:$A,$A9,Meciuri!$X:$X),2),"") | M9: =IFERROR(ROUND(AVERAGEIF(Meciuri!$A:$A,$A9,Meciuri!$P:$P),2),"") | N9: =SUMIF(Meciuri!$A:$A,$A9,Meciuri!$R:$R) | O9: =SUMIF(Meciuri!$A:$A,$A9,Meciuri!$S:$S) | P9: =SUMIF(Meciuri!$A:$A,$A9,Meciuri!$AB:$AB) | Q9: =SUMIF(Meciuri!$A:$A,$A9,Meciuri!$AE:$AE) | R9: =SUMIF(Meciuri!$A:$A,$A9,Meciuri!$AF:$AF) | S9: =SUMIF(Meciuri!$A:$A,$A9,Meciuri!$AD:$AD) | T9: =SUMIF(Meciuri!$A:$A,$A9,Meciuri!$AG:$AG) | U9: =SUMIF(Meciuri!$A:$A,$A9,Meciuri!$AH:$AH) | V9: =SUMIF(Meciuri!$A:$A,$A9,Meciuri!$AI:$AI) | W9: =SUMIF(Meciuri!$A:$A,$A9,Meciuri!$AN:$AN) | X9: Remo Freuler | Y9: 7.75
A10: Scotland | B10: =COUNTIF(Meciuri!$A:$A,$A10) | C10: =SUMIF(Meciuri!$A:$A,$A10,Meciuri!$F:$F) | D10: =IFERROR(ROUND(AVERAGEIF(Meciuri!$A:$A,$A10,Meciuri!$F:$F),2),"") | E10: =SUMIF(Meciuri!$A:$A,$A10,Meciuri!$G:$G) | F10: =IFERROR(ROUND(AVERAGEIF(Meciuri!$A:$A,$A10,Meciuri!$G:$G),2),"") | G10: =SUMIF(Meciuri!$A:$A,$A10,Meciuri!$H:$H) | H10: =IFERROR(ROUND(AVERAGEIF(Meciuri!$A:$A,$A10,Meciuri!$H:$H),2),"") | I10: =SUMIF(Meciuri!$A:$A,$A10,Meciuri!$K:$K) | J10: =SUMIF(Meciuri!$A:$A,$A10,Meciuri!$M:$M) | K10: =SUMIF(Meciuri!$A:$A,$A10,Meciuri!$X:$X) | L10: =IFERROR(ROUND(AVERAGEIF(Meciuri!$A:$A,$A10,Meciuri!$X:$X),2),"") | M10: =IFERROR(ROUND(AVERAGEIF(Meciuri!$A:$A,$A10,Meciuri!$P:$P),2),"") | N10: =SUMIF(Meciuri!$A:$A,$A10,Meciuri!$R:$R) | O10: =SUMIF(Meciuri!$A:$A,$A10,Meciuri!$S:$S) | P10: =SUMIF(Meciuri!$A:$A,$A10,Meciuri!$AB:$AB) | Q10: =SUMIF(Meciuri!$A:$A,$A10,Meciuri!$AE:$AE) | R10: =SUMIF(Meciuri!$A:$A,$A10,Meciuri!$AF:$AF) | S10: =SUMIF(Meciuri!$A:$A,$A10,Meciuri!$AD:$AD) | T10: =SUMIF(Meciuri!$A:$A,$A10,Meciuri!$AG:$AG) | U10: =SUMIF(Meciuri!$A:$A,$A10,Meciuri!$AH:$AH) | V10: =SUMIF(Meciuri!$A:$A,$A10,Meciuri!$AI:$AI) | W10: =SUMIF(Meciuri!$A:$A,$A10,Meciuri!$AN:$AN) | X10: Andy Robertson | Y10: 7.3
A11: Spain | B11: =COUNTIF(Meciuri!$A:$A,$A11) | C11: =SUMIF(Meciuri!$A:$A,$A11,Meciuri!$F:$F) | D11: =IFERROR(ROUND(AVERAGEIF(Meciuri!$A:$A,$A11,Meciuri!$F:$F),2),"") | E11: =SUMIF(Meciuri!$A:$A,$A11,Meciuri!$G:$G) | F11: =IFERROR(ROUND(AVERAGEIF(Meciuri!$A:$A,$A11,Meciuri!$G:$G),2),"") | G11: =SUMIF(Meciuri!$A:$A,$A11,Meciuri!$H:$H) | H11: =IFERROR(ROUND(AVERAGEIF(Meciuri!$A:$A,$A11,Meciuri!$H:$H),2),"") | I11: =SUMIF(Meciuri!$A:$A,$A11,Meciuri!$K:$K) | J11: =SUMIF(Meciuri!$A:$A,$A11,Meciuri!$M:$M) | K11: =SUMIF(Meciuri!$A:$A,$A11,Meciuri!$X:$X) | L11: =IFERROR(ROUND(AVERAGEIF(Meciuri!$A:$A,$A11,Meciuri!$X:$X),2),"") | M11: =IFERROR(ROUND(AVERAGEIF(Meciuri!$A:$A,$A11,Meciuri!$P:$P),2),"") | N11: =SUMIF(Meciuri!$A:$A,$A11,Meciuri!$R:$R) | O11: =SUMIF(Meciuri!$A:$A,$A11,Meciuri!$S:$S) | P11: =SUMIF(Meciuri!$A:$A,$A11,Meciuri!$AB:$AB) | Q11: =SUMIF(Meciuri!$A:$A,$A11,Meciuri!$AE:$AE) | R11: =SUMIF(Meciuri!$A:$A,$A11,Meciuri!$AF:$AF) | S11: =SUMIF(Meciuri!$A:$A,$A11,Meciuri!$AD:$AD) | T11: =SUMIF(Meciuri!$A:$A,$A11,Meciuri!$AG:$AG) | U11: =SUMIF(Meciuri!$A:$A,$A11,Meciuri!$AH:$AH) | V11: =SUMIF(Meciuri!$A:$A,$A11,Meciuri!$AI:$AI) | W11: =SUMIF(Meciuri!$A:$A,$A11,Meciuri!$AN:$AN) | X11: Pedri | Y11: 8.43
A12: Austria | B12: =COUNTIF(Meciuri!$A:$A,$A12) | C12: =SUMIF(Meciuri!$A:$A,$A12,Meciuri!$F:$F) | D12: =IFERROR(ROUND(AVERAGEIF(Meciuri!$A:$A,$A12,Meciuri!$F:$F),2),"") | E12: =SUMIF(Meciuri!$A:$A,$A12,Meciuri!$G:$G) | F12: =IFERROR(ROUND(AVERAGEIF(Meciuri!$A:$A,$A12,Meciuri!$G:$G),2),"") | G12: =SUMIF(Meciuri!$A:$A,$A12,Meciuri!$H:$H) | H12: =IFERROR(ROUND(AVERAGEIF(Meciuri!$A:$A,$A12,Meciuri!$H:$H),2),"") | I12: =SUMIF(Meciuri!$A:$A,$A12,Meciuri!$K:$K) | J12: =SUMIF(Meciuri!$A:$A,$A12,Meciuri!$M:$M) | K12: =SUMIF(Meciuri!$A:$A,$A12,Meciuri!$X:$X) | L12: =IFERROR(ROUND(AVERAGEIF(Meciuri!$A:$A,$A12,Meciuri!$X:$X),2),"") | M12: =IFERROR(ROUND(AVERAGEIF(Meciuri!$A:$A,$A12,Meciuri!$P:$P),2),"") | N12: =SUMIF(Meciuri!$A:$A,$A12,Meciuri!$R:$R) | O12: =SUMIF(Meciuri!$A:$A,$A12,Meciuri!$S:$S) | P12: =SUMIF(Meciuri!$A:$A,$A12,Meciuri!$AB:$AB) | Q12: =SUMIF(Meciuri!$A:$A,$A12,Meciuri!$AE:$AE) | R12: =SUMIF(Meciuri!$A:$A,$A12,Meciuri!$AF:$AF) | S12: =SUMIF(Meciuri!$A:$A,$A12,Meciuri!$AD:$AD) | T12: =SUMIF(Meciuri!$A:$A,$A12,Meciuri!$AG:$AG) | U12: =SUMIF(Meciuri!$A:$A,$A12,Meciuri!$AH:$AH) | V12: =SUMIF(Meciuri!$A:$A,$A12,Meciuri!$AI:$AI) | W12: =SUMIF(Meciuri!$A:$A,$A12,Meciuri!$AN:$AN) | X12: Marko Arnautović | Y12: 7.87
A13: Belgium | B13: =COUNTIF(Meciuri!$A:$A,$A13) | C13: =SUMIF(Meciuri!$A:$A,$A13,Meciuri!$F:$F) | D13: =IFERROR(ROUND(AVERAGEIF(Meciuri!$A:$A,$A13,Meciuri!$F:$F),2),"") | E13: =SUMIF(Meciuri!$A:$A,$A13,Meciuri!$G:$G) | F13: =IFERROR(ROUND(AVERAGEIF(Meciuri!$A:$A,$A13,Meciuri!$G:$G),2),"") | G13: =SUMIF(Meciuri!$A:$A,$A13,Meciuri!$H:$H) | H13: =IFERROR(ROUND(AVERAGEIF(Meciuri!$A:$A,$A13,Meciuri!$H:$H),2),"") | I13: =SUMIF(Meciuri!$A:$A,$A13,Meciuri!$K:$K) | J13: =SUMIF(Meciuri!$A:$A,$A13,Meciuri!$M:$M) | K13: =SUMIF(Meciuri!$A:$A,$A13,Meciuri!$X:$X) | L13: =IFERROR(ROUND(AVERAGEIF(Meciuri!$A:$A,$A13,Meciuri!$X:$X),2),"") | M13: =IFERROR(ROUND(AVERAGEIF(Meciuri!$A:$A,$A13,Meciuri!$P:$P),2),"") | N13: =SUMIF(Meciuri!$A:$A,$A13,Meciuri!$R:$R) | O13: =SUMIF(Meciuri!$A:$A,$A13,Meciuri!$S:$S) | P13: =SUMIF(Meciuri!$A:$A,$A13,Meciuri!$AB:$AB) | Q13: =SUMIF(Meciuri!$A:$A,$A13,Meciuri!$AE:$AE) | R13: =SUMIF(Meciuri!$A:$A,$A13,Meciuri!$AF:$AF) | S13: =SUMIF(Meciuri!$A:$A,$A13,Meciuri!$AD:$AD) | T13: =SUMIF(Meciuri!$A:$A,$A13,Meciuri!$AG:$AG) | U13: =SUMIF(Meciuri!$A:$A,$A13,Meciuri!$AH:$AH) | V13: =SUMIF(Meciuri!$A:$A,$A13,Meciuri!$AI:$AI) | W13: =SUMIF(Meciuri!$A:$A,$A13,Meciuri!$AN:$AN) | X13: Jérémy Doku | Y13: 8.32
... A24: Algeria | B24: =COUNTIF(Meciuri!$A:$A,$A24) | C24: =SUMIF(Meciuri!$A:$A,$A24,Meciuri!$F:$F) | D24: =IFERROR(ROUND(AVERAGEIF(Meciuri!$A:$A,$A24,Meciuri!$F:$F),2),"") | E24: =SUMIF(Meciuri!$A:$A,$A24,Meciuri!$G:$G) | F24: =IFERROR(ROUND(AVERAGEIF(Meciuri!$A:$A,$A24,Meciuri!$G:$G),2),"") | G24: =SUMIF(Meciuri!$A:$A,$A24,Meciuri!$H:$H) | H24: =IFERROR(ROUND(AVERAGEIF(Meciuri!$A:$A,$A24,Meciuri!$H:$H),2),"") | I24: =SUMIF(Meciuri!$A:$A,$A24,Meciuri!$K:$K) | J24: =SUMIF(Meciuri!$A:$A,$A24,Meciuri!$M:$M) | K24: =SUMIF(Meciuri!$A:$A,$A24,Meciuri!$X:$X) | L24: =IFERROR(ROUND(AVERAGEIF(Meciuri!$A:$A,$A24,Meciuri!$X:$X),2),"") | M24: =IFERROR(ROUND(AVERAGEIF(Meciuri!$A:$A,$A24,Meciuri!$P:$P),2),"") | N24: =SUMIF(Meciuri!$A:$A,$A24,Meciuri!$R:$R) | O24: =SUMIF(Meciuri!$A:$A,$A24,Meciuri!$S:$S) | P24: =SUMIF(Meciuri!$A:$A,$A24,Meciuri!$AB:$AB) | Q24: =SUMIF(Meciuri!$A:$A,$A24,Meciuri!$AE:$AE) | R24: =SUMIF(Meciuri!$A:$A,$A24,Meciuri!$AF:$AF) | S24: =SUMIF(Meciuri!$A:$A,$A24,Meciuri!$AD:$AD) | T24: =SUMIF(Meciuri!$A:$A,$A24,Meciuri!$AG:$AG) | U24: =SUMIF(Meciuri!$A:$A,$A24,Meciuri!$AH:$AH) | V24: =SUMIF(Meciuri!$A:$A,$A24,Meciuri!$AI:$AI) | W24: =SUMIF(Meciuri!$A:$A,$A24,Meciuri!$AN:$AN) | X24: Mohamed Amoura | Y24: 8.33
A25: Cape Verde | B25: =COUNTIF(Meciuri!$A:$A,$A25) | C25: =SUMIF(Meciuri!$A:$A,$A25,Meciuri!$F:$F) | D25: =IFERROR(ROUND(AVERAGEIF(Meciuri!$A:$A,$A25,Meciuri!$F:$F),2),"") | E25: =SUMIF(Meciuri!$A:$A,$A25,Meciuri!$G:$G) | F25: =IFERROR(ROUND(AVERAGEIF(Meciuri!$A:$A,$A25,Meciuri!$G:$G),2),"") | G25: =SUMIF(Meciuri!$A:$A,$A25,Meciuri!$H:$H) | H25: =IFERROR(ROUND(AVERAGEIF(Meciuri!$A:$A,$A25,Meciuri!$H:$H),2),"") | I25: =SUMIF(Meciuri!$A:$A,$A25,Meciuri!$K:$K) | J25: =SUMIF(Meciuri!$A:$A,$A25,Meciuri!$M:$M) | K25: =SUMIF(Meciuri!$A:$A,$A25,Meciuri!$X:$X) | L25: =IFERROR(ROUND(AVERAGEIF(Meciuri!$A:$A,$A25,Meciuri!$X:$X),2),"") | M25: =IFERROR(ROUND(AVERAGEIF(Meciuri!$A:$A,$A25,Meciuri!$P:$P),2),"") | N25: =SUMIF(Meciuri!$A:$A,$A25,Meciuri!$R:$R) | O25: =SUMIF(Meciuri!$A:$A,$A25,Meciuri!$S:$S) | P25: =SUMIF(Meciuri!$A:$A,$A25,Meciuri!$AB:$AB) | Q25: =SUMIF(Meciuri!$A:$A,$A25,Meciuri!$AE:$AE) | R25: =SUMIF(Meciuri!$A:$A,$A25,Meciuri!$AF:$AF) | S25: =SUMIF(Meciuri!$A:$A,$A25,Meciuri!$AD:$AD) | T25: =SUMIF(Meciuri!$A:$A,$A25,Meciuri!$AG:$AG) | U25: =SUMIF(Meciuri!$A:$A,$A25,Meciuri!$AH:$AH) | V25: =SUMIF(Meciuri!$A:$A,$A25,Meciuri!$AI:$AI) | W25: =SUMIF(Meciuri!$A:$A,$A25,Meciuri!$AN:$AN) | X25: —
A26: Egypt | B26: =COUNTIF(Meciuri!$A:$A,$A26) | C26: =SUMIF(Meciuri!$A:$A,$A26,Meciuri!$F:$F) | D26: =IFERROR(ROUND(AVERAGEIF(Meciuri!$A:$A,$A26,Meciuri!$F:$F),2),"") | E26: =SUMIF(Meciuri!$A:$A,$A26,Meciuri!$G:$G) | F26: =IFERROR(ROUND(AVERAGEIF(Meciuri!$A:$A,$A26,Meciuri!$G:$G),2),"") | G26: =SUMIF(Meciuri!$A:$A,$A26,Meciuri!$H:$H) | H26: =IFERROR(ROUND(AVERAGEIF(Meciuri!$A:$A,$A26,Meciuri!$H:$H),2),"") | I26: =SUMIF(Meciuri!$A:$A,$A26,Meciuri!$K:$K) | J26: =SUMIF(Meciuri!$A:$A,$A26,Meciuri!$M:$M) | K26: =SUMIF(Meciuri!$A:$A,$A26,Meciuri!$X:$X) | L26: =IFERROR(ROUND(AVERAGEIF(Meciuri!$A:$A,$A26,Meciuri!$X:$X),2),"") | M26: =IFERROR(ROUND(AVERAGEIF(Meciuri!$A:$A,$A26,Meciuri!$P:$P),2),"") | N26: =SUMIF(Meciuri!$A:$A,$A26,Meciuri!$R:$R) | O26: =SUMIF(Meciuri!$A:$A,$A26,Meciuri!$S:$S) | P26: =SUMIF(Meciuri!$A:$A,$A26,Meciuri!$AB:$AB) | Q26: =SUMIF(Meciuri!$A:$A,$A26,Meciuri!$AE:$AE) | R26: =SUMIF(Meciuri!$A:$A,$A26,Meciuri!$AF:$AF) | S26: =SUMIF(Meciuri!$A:$A,$A26,Meciuri!$AD:$AD) | T26: =SUMIF(Meciuri!$A:$A,$A26,Meciuri!$AG:$AG) | U26: =SUMIF(Meciuri!$A:$A,$A26,Meciuri!$AH:$AH) | V26: =SUMIF(Meciuri!$A:$A,$A26,Meciuri!$AI:$AI) | W26: =SUMIF(Meciuri!$A:$A,$A26,Meciuri!$AN:$AN) | X26: —
A27: Ghana | B27: =COUNTIF(Meciuri!$A:$A,$A27) | C27: =SUMIF(Meciuri!$A:$A,$A27,Meciuri!$F:$F) | D27: =IFERROR(ROUND(AVERAGEIF(Meciuri!$A:$A,$A27,Meciuri!$F:$F),2),"") | E27: =SUMIF(Meciuri!$A:$A,$A27,Meciuri!$G:$G) | F27: =IFERROR(ROUND(AVERAGEIF(Meciuri!$A:$A,$A27,Meciuri!$G:$G),2),"") | G27: =SUMIF(Meciuri!$A:$A,$A27,Meciuri!$H:$H) | H27: =IFERROR(ROUND(AVERAGEIF(Meciuri!$A:$A,$A27,Meciuri!$H:$H),2),"") | I27: =SUMIF(Meciuri!$A:$A,$A27,Meciuri!$K:$K) | J27: =SUMIF(Meciuri!$A:$A,$A27,Meciuri!$M:$M) | K27: =SUMIF(Meciuri!$A:$A,$A27,Meciuri!$X:$X) | L27: =IFERROR(ROUND(AVERAGEIF(Meciuri!$A:$A,$A27,Meciuri!$X:$X),2),"") | M27: =IFERROR(ROUND(AVERAGEIF(Meciuri!$A:$A,$A27,Meciuri!$P:$P),2),"") | N27: =SUMIF(Meciuri!$A:$A,$A27,Meciuri!$R:$R) | O27: =SUMIF(Meciuri!$A:$A,$A27,Meciuri!$S:$S) | P27: =SUMIF(Meciuri!$A:$A,$A27,Meciuri!$AB:$AB) | Q27: =SUMIF(Meciuri!$A:$A,$A27,Meciuri!$AE:$AE) | R27: =SUMIF(Meciuri!$A:$A,$A27,Meciuri!$AF:$AF) | S27: =SUMIF(Meciuri!$A:$A,$A27,Meciuri!$AD:$AD) | T27: =SUMIF(Meciuri!$A:$A,$A27,Meciuri!$AG:$AG) | U27: =SUMIF(Meciuri!$A:$A,$A27,Meciuri!$AH:$AH) | V27: =SUMIF(Meciuri!$A:$A,$A27,Meciuri!$AI:$AI) | W27: =SUMIF(Meciuri!$A:$A,$A27,Meciuri!$AN:$AN) | X27: —
A28: Ivory Coast | B28: =COUNTIF(Meciuri!$A:$A,$A28) | C28: =SUMIF(Meciuri!$A:$A,$A28,Meciuri!$F:$F) | D28: =IFERROR(ROUND(AVERAGEIF(Meciuri!$A:$A,$A28,Meciuri!$F:$F),2),"") | E28: =SUMIF(Meciuri!$A:$A,$A28,Meciuri!$G:$G) | F28: =IFERROR(ROUND(AVERAGEIF(Meciuri!$A:$A,$A28,Meciuri!$G:$G),2),"") | G28: =SUMIF(Meciuri!$A:$A,$A28,Meciuri!$H:$H) | H28: =IFERROR(ROUND(AVERAGEIF(Meciuri!$A:$A,$A28,Meciuri!$H:$H),2),"") | I28: =SUMIF(Meciuri!$A:$A,$A28,Meciuri!$K:$K) | J28: =SUMIF(Meciuri!$A:$A,$A28,Meciuri!$M:$M) | K28: =SUMIF(Meciuri!$A:$A,$A28,Meciuri!$X:$X) | L28: =IFERROR(ROUND(AVERAGEIF(Meciuri!$A:$A,$A28,Meciuri!$X:$X),2),"") | M28: =IFERROR(ROUND(AVERAGEIF(Meciuri!$A:$A,$A28,Meciuri!$P:$P),2),"") | N28: =SUMIF(Meciuri!$A:$A,$A28,Meciuri!$R:$R) | O28: =SUMIF(Meciuri!$A:$A,$A28,Meciuri!$S:$S) | P28: =SUMIF(Meciuri!$A:$A,$A28,Meciuri!$AB:$AB) | Q28: =SUMIF(Meciuri!$A:$A,$A28,Meciuri!$AE:$AE) | R28: =SUMIF(Meciuri!$A:$A,$A28,Meciuri!$AF:$AF) | S28: =SUMIF(Meciuri!$A:$A,$A28,Meciuri!$AD:$AD) | T28: =SUMIF(Meciuri!$A:$A,$A28,Meciuri!$AG:$AG) | U28: =SUMIF(Meciuri!$A:$A,$A28,Meciuri!$AH:$AH) | V28: =SUMIF(Meciuri!$A:$A,$A28,Meciuri!$AI:$AI) | W28: =SUMIF(Meciuri!$A:$A,$A28,Meciuri!$AN:$AN) | X28: —
A29: Morocco | B29: =COUNTIF(Meciuri!$A:$A,$A29) | C29: =SUMIF(Meciuri!$A:$A,$A29,Meciuri!$F:$F) | D29: =IFERROR(ROUND(AVERAGEIF(Meciuri!$A:$A,$A29,Meciuri!$F:$F),2),"") | E29: =SUMIF(Meciuri!$A:$A,$A29,Meciuri!$G:$G) | F29: =IFERROR(ROUND(AVERAGEIF(Meciuri!$A:$A,$A29,Meciuri!$G:$G),2),"") | G29: =SUMIF(Meciuri!$A:$A,$A29,Meciuri!$H:$H) | H29: =IFERROR(ROUND(AVERAGEIF(Meciuri!$A:$A,$A29,Meciuri!$H:$H),2),"") | I29: =SUMIF(Meciuri!$A:$A,$A29,Meciuri!$K:$K) | J29: =SUMIF(Meciuri!$A:$A,$A29,Meciuri!$M:$M) | K29: =SUMIF(Meciuri!$A:$A,$A29,Meciuri!$X:$X) | L29: =IFERROR(ROUND(AVERAGEIF(Meciuri!$A:$A,$A29,Meciuri!$X:$X),2),"") | M29: =IFERROR(ROUND(AVERAGEIF(Meciuri!$A:$A,$A29,Meciuri!$P:$P),2),"") | N29: =SUMIF(Meciuri!$A:$A,$A29,Meciuri!$R:$R) | O29: =SUMIF(Meciuri!$A:$A,$A29,Meciuri!$S:$S) | P29: =SUMIF(Meciuri!$A:$A,$A29,Meciuri!$AB:$AB) | Q29: =SUMIF(Meciuri!$A:$A,$A29,Meciuri!$AE:$AE) | R29: =SUMIF(Meciuri!$A:$A,$A29,Meciuri!$AF:$AF) | S29: =SUMIF(Meciuri!$A:$A,$A29,Meciuri!$AD:$AD) | T29: =SUMIF(Meciuri!$A:$A,$A29,Meciuri!$AG:$AG) | U29: =SUMIF(Meciuri!$A:$A,$A29,Meciuri!$AH:$AH) | V29: =SUMIF(Meciuri!$A:$A,$A29,Meciuri!$AI:$AI) | W29: =SUMIF(Meciuri!$A:$A,$A29,Meciuri!$AN:$AN) | X29: Achraf Hakimi | Y29: 7.85
A30: Senegal | B30: =COUNTIF(Meciuri!$A:$A,$A30) | C30: =SUMIF(Meciuri!$A:$A,$A30,Meciuri!$F:$F) | D30: =IFERROR(ROUND(AVERAGEIF(Meciuri!$A:$A,$A30,Meciuri!$F:$F),2),"") | E30: =SUMIF(Meciuri!$A:$A,$A30,Meciuri!$G:$G) | F30: =IFERROR(ROUND(AVERAGEIF(Meciuri!$A:$A,$A30,Meciuri!$G:$G),2),"") | G30: =SUMIF(Meciuri!$A:$A,$A30,Meciuri!$H:$H) | H30: =IFERROR(ROUND(AVERAGEIF(Meciuri!$A:$A,$A30,Meciuri!$H:$H),2),"") | I30: =SUMIF(Meciuri!$A:$A,$A30,Meciuri!$K:$K) | J30: =SUMIF(Meciuri!$A:$A,$A30,Meciuri!$M:$M) | K30: =SUMIF(Meciuri!$A:$A,$A30,Meciuri!$X:$X) | L30: =IFERROR(ROUND(AVERAGEIF(Meciuri!$A:$A,$A30,Meciuri!$X:$X),2),"") | M30: =IFERROR(ROUND(AVERAGEIF(Meciuri!$A:$A,$A30,Meciuri!$P:$P),2),"") | N30: =SUMIF(Meciuri!$A:$A,$A30,Meciuri!$R:$R) | O30: =SUMIF(Meciuri!$A:$A,$A30,Meciuri!$S:$S) | P30: =SUMIF(Meciuri!$A:$A,$A30,Meciuri!$AB:$AB) | Q30: =SUMIF(Meciuri!$A:$A,$A30,Meciuri!$AE:$AE) | R30: =SUMIF(Meciuri!$A:$A,$A30,Meciuri!$AF:$AF) | S30: =SUMIF(Meciuri!$A:$A,$A30,Meciuri!$AD:$AD) | T30: =SUMIF(Meciuri!$A:$A,$A30,Meciuri!$AG:$AG) | U30: =SUMIF(Meciuri!$A:$A,$A30,Meciuri!$AH:$AH) | V30: =SUMIF(Meciuri!$A:$A,$A30,Meciuri!$AI:$AI) | W30: =SUMIF(Meciuri!$A:$A,$A30,Meciuri!$AN:$AN) | X30: Kalidou Koulibaly | Y30: 7.92
A31: South Africa | B31: =COUNTIF(Meciuri!$A:$A,$A31) | C31: =SUMIF(Meciuri!$A:$A,$A31,Meciuri!$F:$F) | D31: =IFERROR(ROUND(AVERAGEIF(Meciuri!$A:$A,$A31,Meciuri!$F:$F),2),"") | E31: =SUMIF(Meciuri!$A:$A,$A31,Meciuri!$G:$G) | F31: =IFERROR(ROUND(AVERAGEIF(Meciuri!$A:$A,$A31,Meciuri!$G:$G),2),"") | G31: =SUMIF(Meciuri!$A:$A,$A31,Meciuri!$H:$H) | H31: =IFERROR(ROUND(AVERAGEIF(Meciuri!$A:$A,$A31,Meciuri!$H:$H),2),"") | I31: =SUMIF(Meciuri!$A:$A,$A31,Meciuri!$K:$K) | J31: =SUMIF(Meciuri!$A:$A,$A31,Meciuri!$M:$M) | K31: =SUMIF(Meciuri!$A:$A,$A31,Meciuri!$X:$X) | L31: =IFERROR(ROUND(AVERAGEIF(Meciuri!$A:$A,$A31,Meciuri!$X:$X),2),"") | M31: =IFERROR(ROUND(AVERAGEIF(Meciuri!$A:$A,$A31,Meciuri!$P:$P),2),"") | N31: =SUMIF(Meciuri!$A:$A,$A31,Meciuri!$R:$R) | O31: =SUMIF(Meciuri!$A:$A,$A31,Meciuri!$S:$S) | P31: =SUMIF(Meciuri!$A:$A,$A31,Meciuri!$AB:$AB) | Q31: =SUMIF(Meciuri!$A:$A,$A31,Meciuri!$AE:$AE) | R31: =SUMIF(Meciuri!$A:$A,$A31,Meciuri!$AF:$AF) | S31: =SUMIF(Meciuri!$A:$A,$A31,Meciuri!$AD:$AD) | T31: =SUMIF(Meciuri!$A:$A,$A31,Meciuri!$AG:$AG) | U31: =SUMIF(Meciuri!$A:$A,$A31,Meciuri!$AH:$AH) | V31: =SUMIF(Meciuri!$A:$A,$A31,Meciuri!$AI:$AI) | W31: =SUMIF(Meciuri!$A:$A,$A31,Meciuri!$AN:$AN) | X31: Oswin Appollis | Y31: 7.75
A32: Tunisia | B32: =COUNTIF(Meciuri!$A:$A,$A32) | C32: =SUMIF(Meciuri!$A:$A,$A32,Meciuri!$F:$F) | D32: =IFERROR(ROUND(AVERAGEIF(Meciuri!$A:$A,$A32,Meciuri!$F:$F),2),"") | E32: =SUMIF(Meciuri!$A:$A,$A32,Meciuri!$G:$G) | F32: =IFERROR(ROUND(AVERAGEIF(Meciuri!$A:$A,$A32,Meciuri!$G:$G),2),"") | G32: =SUMIF(Meciuri!$A:$A,$A32,Meciuri!$H:$H) | H32: =IFERROR(ROUND(AVERAGEIF(Meciuri!$A:$A,$A32,Meciuri!$H:$H),2),"") | I32: =SUMIF(Meciuri!$A:$A,$A32,Meciuri!$K:$K) | J32: =SUMIF(Meciuri!$A:$A,$A32,Meciuri!$M:$M) | K32: =SUMIF(Meciuri!$A:$A,$A32,Meciuri!$X:$X) | L32: =IFERROR(ROUND(AVERAGEIF(Meciuri!$A:$A,$A32,Meciuri!$X:$X),2),"") | M32: =IFERROR(ROUND(AVERAGEIF(Meciuri!$A:$A,$A32,Meciuri!$P:$P),2),"") | N32: =SUMIF(Meciuri!$A:$A,$A32,Meciuri!$R:$R) | O32: =SUMIF(Meciuri!$A:$A,$A32,Meciuri!$S:$S) | P32: =SUMIF(Meciuri!$A:$A,$A32,Meciuri!$AB:$AB) | Q32: =SUMIF(Meciuri!$A:$A,$A32,Meciuri!$AE:$AE) | R32: =SUMIF(Meciuri!$A:$A,$A32,Meciuri!$AF:$AF) | S32: =SUMIF(Meciuri!$A:$A,$A32,Meciuri!$AD:$AD) | T32: =SUMIF(Meciuri!$A:$A,$A32,Meciuri!$AG:$AG) | U32: =SUMIF(Meciuri!$A:$A,$A32,Meciuri!$AH:$AH) | V32: =SUMIF(Meciuri!$A:$A,$A32,Meciuri!$AI:$AI) | W32: =SUMIF(Meciuri!$A:$A,$A32,Meciuri!$AN:$AN) | X32: Hannibal Mejbri | Y32: 7.8
A33: Panama | B33: =COUNTIF(Meciuri!$A:$A,$A33) | C33: =SUMIF(Meciuri!$A:$A,$A33,Meciuri!$F:$F) | D33: =IFERROR(ROUND(AVERAGEIF(Meciuri!$A:$A,$A33,Meciuri!$F:$F),2),"") | E33: =SUMIF(Meciuri!$A:$A,$A33,Meciuri!$G:$G) | F33: =IFERROR(ROUND(AVERAGEIF(Meciuri!$A:$A,$A33,Meciuri!$G:$G),2),"") | G33: =SUMIF(Meciuri!$A:$A,$A33,Meciuri!$H:$H) | H33: =IFERROR(ROUND(AVERAGEIF(Meciuri!$A:$A,$A33,Meciuri!$H:$H),2),"") | I33: =SUMIF(Meciuri!$A:$A,$A33,Meciuri!$K:$K) | J33: =SUMIF(Meciuri!$A:$A,$A33,Meciuri!$M:$M) | K33: =SUMIF(Meciuri!$A:$A,$A33,Meciuri!$X:$X) | L33: =IFERROR(ROUND(AVERAGEIF(Meciuri!$A:$A,$A33,Meciuri!$X:$X),2),"") | M33: =IFERROR(ROUND(AVERAGEIF(Meciuri!$A:$A,$A33,Meciuri!$P:$P),2),"") | N33: =SUMIF(Meciuri!$A:$A,$A33,Meciuri!$R:$R) | O33: =SUMIF(Meciuri!$A:$A,$A33,Meciuri!$S:$S) | P33: =SUMIF(Meciuri!$A:$A,$A33,Meciuri!$AB:$AB) | Q33: =SUMIF(Meciuri!$A:$A,$A33,Meciuri!$AE:$AE) | R33: =SUMIF(Meciuri!$A:$A,$A33,Meciuri!$AF:$AF) | S33: =SUMIF(Meciuri!$A:$A,$A33,Meciuri!$AD:$AD) | T33: =SUMIF(Meciuri!$A:$A,$A33,Meciuri!$AG:$AG) | U33: =SUMIF(Meciuri!$A:$A,$A33,Meciuri!$AH:$AH) | V33: =SUMIF(Meciuri!$A:$A,$A33,Meciuri!$AI:$AI) | W33: =SUMIF(Meciuri!$A:$A,$A33,Meciuri!$AN:$AN) | X33: Amir Murillo | Y33: 7.49
A34: Curacao | B34: =COUNTIF(Meciuri!$A:$A,$A34) | C34: =SUMIF(Meciuri!$A:$A,$A34,Meciuri!$F:$F) | D34: =IFERROR(ROUND(AVERAGEIF(Meciuri!$A:$A,$A34,Meciuri!$F:$F),2),"") | E34: =SUMIF(Meciuri!$A:$A,$A34,Meciuri!$G:$G) | F34: =IFERROR(ROUND(AVERAGEIF(Meciuri!$A:$A,$A34,Meciuri!$G:$G),2),"") | G34: =SUMIF(Meciuri!$A:$A,$A34,Meciuri!$H:$H) | H34: =IFERROR(ROUND(AVERAGEIF(Meciuri!$A:$A,$A34,Meciuri!$H:$H),2),"") | I34: =SUMIF(Meciuri!$A:$A,$A34,Meciuri!$K:$K) | J34: =SUMIF(Meciuri!$A:$A,$A34,Meciuri!$M:$M) | K34: =SUMIF(Meciuri!$A:$A,$A34,Meciuri!$X:$X) | L34: =IFERROR(ROUND(AVERAGEIF(Meciuri!$A:$A,$A34,Meciuri!$X:$X),2),"") | M34: =IFERROR(ROUND(AVERAGEIF(Meciuri!$A:$A,$A34,Meciuri!$P:$P),2),"") | N34: =SUMIF(Meciuri!$A:$A,$A34,Meciuri!$R:$R) | O34: =SUMIF(Meciuri!$A:$A,$A34,Meciuri!$S:$S) | P34: =SUMIF(Meciuri!$A:$A,$A34,Meciuri!$AB:$AB) | Q34: =SUMIF(Meciuri!$A:$A,$A34,Meciuri!$AE:$AE) | R34: =SUMIF(Meciuri!$A:$A,$A34,Meciuri!$AF:$AF) | S34: =SUMIF(Meciuri!$A:$A,$A34,Meciuri!$AD:$AD) | T34: =SUMIF(Meciuri!$A:$A,$A34,Meciuri!$AG:$AG) | U34: =SUMIF(Meciuri!$A:$A,$A34,Meciuri!$AH:$AH) | V34: =SUMIF(Meciuri!$A:$A,$A34,Meciuri!$AI:$AI) | W34: =SUMIF(Meciuri!$A:$A,$A34,Meciuri!$AN:$AN) | X34: Juninho Bacuna | Y34: 7.57
A35: Haiti | B35: =COUNTIF(Meciuri!$A:$A,$A35) | C35: =SUMIF(Meciuri!$A:$A,$A35,Meciuri!$F:$F) | D35: =IFERROR(ROUND(AVERAGEIF(Meciuri!$A:$A,$A35,Meciuri!$F:$F),2),"") | E35: =SUMIF(Meciuri!$A:$A,$A35,Meciuri!$G:$G) | F35: =IFERROR(ROUND(AVERAGEIF(Meciuri!$A:$A,$A35,Meciuri!$G:$G),2),"") | G35: =SUMIF(Meciuri!$A:$A,$A35,Meciuri!$H:$H) | H35: =IFERROR(ROUND(AVERAGEIF(Meciuri!$A:$A,$A35,Meciuri!$H:$H),2),"") | I35: =SUMIF(Meciuri!$A:$A,$A35,Meciuri!$K:$K) | J35: =SUMIF(Meciuri!$A:$A,$A35,Meciuri!$M:$M) | K35: =SUMIF(Meciuri!$A:$A,$A35,Meciuri!$X:$X) | L35: =IFERROR(ROUND(AVERAGEIF(Meciuri!$A:$A,$A35,Meciuri!$X:$X),2),"") | M35: =IFERROR(ROUND(AVERAGEIF(Meciuri!$A:$A,$A35,Meciuri!$P:$P),2),"") | N35: =SUMIF(Meciuri!$A:$A,$A35,Meciuri!$R:$R) | O35: =SUMIF(Meciuri!$A:$A,$A35,Meciuri!$S:$S) | P35: =SUMIF(Meciuri!$A:$A,$A35,Meciuri!$AB:$AB) | Q35: =SUMIF(Meciuri!$A:$A,$A35,Meciuri!$AE:$AE) | R35: =SUMIF(Meciuri!$A:$A,$A35,Meciuri!$AF:$AF) | S35: =SUMIF(Meciuri!$A:$A,$A35,Meciuri!$AD:$AD) | T35: =SUMIF(Meciuri!$A:$A,$A35,Meciuri!$AG:$AG) | U35: =SUMIF(Meciuri!$A:$A,$A35,Meciuri!$AH:$AH) | V35: =SUMIF(Meciuri!$A:$A,$A35,Meciuri!$AI:$AI) | W35: =SUMIF(Meciuri!$A:$A,$A35,Meciuri!$AN:$AN) | X35: Fafà Picault | Y35: 7.78
A36: Australia | B36: =COUNTIF(Meciuri!$A:$A,$A36) | C36: =SUMIF(Meciuri!$A:$A,$A36,Meciuri!$F:$F) | D36: =IFERROR(ROUND(AVERAGEIF(Meciuri!$A:$A,$A36,Meciuri!$F:$F),2),"") | E36: =SUMIF(Meciuri!$A:$A,$A36,Meciuri!$G:$G) | F36: =IFERROR(ROUND(AVERAGEIF(Meciuri!$A:$A,$A36,Meciuri!$G:$G),2),"") | G36: =SUMIF(Meciuri!$A:$A,$A36,Meciuri!$H:$H) | H36: =IFERROR(ROUND(AVERAGEIF(Meciuri!$A:$A,$A36,Meciuri!$H:$H),2),"") | I36: =SUMIF(Meciuri!$A:$A,$A36,Meciuri!$K:$K) | J36: =SUMIF(Meciuri!$A:$A,$A36,Meciuri!$M:$M) | K36: =SUMIF(Meciuri!$A:$A,$A36,Meciuri!$X:$X) | L36: =IFERROR(ROUND(AVERAGEIF(Meciuri!$A:$A,$A36,Meciuri!$X:$X),2),"") | M36: =IFERROR(ROUND(AVERAGEIF(Meciuri!$A:$A,$A36,Meciuri!$P:$P),2),"") | N36: =SUMIF(Meciuri!$A:$A,$A36,Meciuri!$R:$R) | O36: =SUMIF(Meciuri!$A:$A,$A36,Meciuri!$S:$S) | P36: =SUMIF(Meciuri!$A:$A,$A36,Meciuri!$AB:$AB) | Q36: =SUMIF(Meciuri!$A:$A,$A36,Meciuri!$AE:$AE) | R36: =SUMIF(Meciuri!$A:$A,$A36,Meciuri!$AF:$AF) | S36: =SUMIF(Meciuri!$A:$A,$A36,Meciuri!$AD:$AD) | T36: =SUMIF(Meciuri!$A:$A,$A36,Meciuri!$AG:$AG) | U36: =SUMIF(Meciuri!$A:$A,$A36,Meciuri!$AH:$AH) | V36: =SUMIF(Meciuri!$A:$A,$A36,Meciuri!$AI:$AI) | W36: =SUMIF(Meciuri!$A:$A,$A36,Meciuri!$AN:$AN) | X36: Harry Souttar | Y36: 7.55
